Workbook

Sheet Summary
A1: PROJECT WORK LOAD TRAKING SHEET
A2: PROJECT | C2: DEPARTMENT | P2: DESIGN
A3: Sr. No. | B3: PROJECT CODE | C3: PROJECT NAME | D3: January | E3: February | F3: March | G3: April | H3: May | I3: June | J3: July | K3: August | L3: September | M3: October | N3: November | O3: December | P3: Total Hrs | Q3: ETC | R3: Over Budget | S3: WK01 | T3: WK02 | U3: WK03 | V3: WK04 | W3: WK05 | X3: WK06 | Y3: WK07 | Z3: WK08 | AA3: WK09 | AB3: WK10 | AC3: WK11 | AD3: WK12 | AE3: WK13 | AF3: WK14 | AG3: WK15 | AH3: WK16 | AI3: WK17 | AJ3: WK18 | AK3: WK19 | AL3: WK20 | AM3: WK21 | AN3: WK22 | AO3: WK23 | AP3: WK24 | AQ3: WK25 | AR3: WK26 | AS3: WK27 | AT3: WK28 | AU3: WK29 | AV3: WK30 | AW3: WK31 | AX3: WK32 | AY3: WK33 | AZ3: WK34 | BA3: WK35 | BB3: WK36 | BC3: WK37 | BD3: WK38 | BE3: WK39 | BF3: WK40 | BG3: WK41 | BH3: WK42 | BI3: WK43 | BJ3: WK44 | BK3: WK45 | BL3: WK46 | BM3: WK47 | BN3: WK48 | BO3: WK49 | BP3: WK50 | BQ3: WK51 | BR3: WK52 | BS3: WK53
A4: 1 | B4: LEAVE | D4: =S4+T4+U4+V4+W4 -> 0 | E4: =X4+Y4+Z4+AA4 -> 0 | F4: =AB4+AC4+AD4+AE4 -> 0 | G4: =AF4+AG4+AH4+AI4+AJ4 -> 0 | H4: =AK4+AL4+AM4+AN4 -> 0 | I4: =AO4+AP4+AQ4+AR4 -> #REF! | J4: =AS4+AT4+AU4+AV4+AW4 -> #REF! | K4: =AX4+AY4+AZ4+BA4 -> 0 | L4: =BB4+BC4+BD4+BE4 -> 0 | M4: =BF4+BG4+BH4+BI4+BJ4 -> 0 | N4: =BK4+BL4+BM4+BN4 -> 0 | O4: =BO4+BP4+BQ4+BR4+BS4 -> 0 | P4: =(SUM(S4:BS4)) -> #REF! | R4: =IF(Q4>P4,Q4-P4,0) -> #REF! | S4: =SUMIF('01'!D:D,Summary!$B4,'01'!E:E) -> 0 | T4: =SUMIF('02'!D:D,Summary!$B4,'02'!E:E) -> 0 | U4: =SUMIF('03'!D:D,Summary!$B4,'03'!E:E) -> 0 | V4: =SUMIF('04'!D:D,Summary!$B4,'04'!E:E) -> 0 | W4: =SUMIF('05'!D:D,Summary!$B4,'05'!E:E) -> 0 | X4: =SUMIF('06'!D:D,Summary!$B4,'06'!E:E) -> 0 | Y4: =SUMIF('07'!D:D,Summary!$B4,'07'!E:E) -> 0 | Z4: =SUMIF('08'!D:D,Summary!$B4,'08'!E:E) -> 0 | AA4: =SUMIF('09'!D:D,Summary!$B4,'09'!E:E) -> 0 | AB4: =SUMIF('10'!D:D,Summary!$B4,'10'!E:E) -> 0 | AC4: =SUMIF('11'!D:D,Summary!$B4,'11'!E:E) -> 0 | AD4: =SUMIF('12'!D:D,Summary!$B4,'12'!E:E) -> 0 | AE4: =SUMIF('13'!D:D,Summary!$B4,'13'!E:E) -> 0 | AF4: =SUMIF('14'!D:D,Summary!$B4,'14'!E:E) -> 0 | AG4: =SUMIF('15'!D:D,Summary!$B4,'15'!E:E) -> 0 | AH4: =SUMIF('16'!D:D,Summary!$B4,'16'!E:E) -> 0 | AI4: =SUMIF('17'!D:D,Summary!$B4,'17'!E:E) -> 0 | AJ4: =SUMIF('18'!D:D,Summary!$B4,'18'!E:E) -> 0 | AK4: =SUMIF('19'!D:D,Summary!$B4,'19'!E:E) -> 0 | AL4: =SUMIF('20'!D:D,Summary!$B4,'20'!E:E) -> 0 | AM4: =SUMIF('21'!D:D,Summary!$B4,'21'!E:E) -> 0 | AN4: =SUMIF('22'!D:D,Summary!$B4,'22'!$E:$E) -> 0 | AO4: =SUMIF(#REF!,Summary!$B4,#REF!) -> #REF! | AP4: =SUMIF(#REF!,Summary!$B4,#REF!) -> #REF! | AQ4: =SUMIF(#REF!,Summary!$B4,#REF!) -> #REF! | AR4: =SUMIF(#REF!,Summary!$B4,#REF!) -> #REF! | AS4: =SUMIF(#REF!,Summary!$B4,#REF!) -> #REF! | AT4: =SUMIF('28'!D:D,Summary!$B4,'28'!E:E) -> 0 | AU4: =SUMIF('29'!D:D,Summary!$B4,'29'!E:E) -> 0 | AV4: =SUMIF('30'!D:D,Summary!$B4,'30'!E:E) -> 0 | AW4: =SUMIF('31'!D:D,Summary!$B4,'31'!E:E) -> 0 | AX4: =SUMIF('32'!D:D,Summary!$B4,'32'!E:E) -> 0 | AY4: =SUMIF('33'!D:D,Summary!$B4,'33'!E:E) -> 0 | AZ4: =SUMIF('34'!D:D,Summary!$B4,'34'!E:E) -> 0 | BA4: =SUMIF('35'!D:D,Summary!$B4,'35'!E:E) -> 0 | BB4: =SUMIF('36'!D:D,Summary!$B4,'36'!E:E) -> 0 | BC4: =SUMIF('37'!D:D,Summary!$B4,'37'!E:E) -> 0 | BD4: =SUMIF('38'!D:D,Summary!$B4,'38'!E:E) -> 0 | BE4: =SUMIF('39'!D:D,Summary!$B4,'39'!E:E) -> 0 | BF4: =SUMIF('40'!D:D,Summary!$B4,'40'!E:E) -> 0 | BG4: =SUMIF('41'!D:D,Summary!$B4,'41'!E:E) -> 0 | BH4: =SUMIF('42'!D:D,Summary!$B4,'42'!E:E) -> 0 | BI4: =SUMIF('43'!D:D,Summary!$B4,'43'!E:E) -> 0 | BJ4: =SUMIF('44'!D:D,Summary!$B4,'44'!E:E) -> 0 | BK4: =SUMIF('45'!D:D,Summary!$B4,'45'!E:E) -> 0 | BL4: =SUMIF('46'!D:D,Summary!$B4,'46'!E:E) -> 0 | BM4: =SUMIF('47'!D:D,Summary!$B4,'47'!E:E) -> 0 | BN4: =SUMIF('48'!D:D,Summary!$B4,'48'!E:E) -> 0 | BO4: =SUMIF('49'!D:D,Summary!$B4,'49'!E:E) -> 0 | BP4: =SUMIF('50'!D:D,Summary!$B4,'50'!E:E) -> 0 | BQ4: =SUMIF('51'!D:D,Summary!$B4,'51'!E:E) -> 0 | BR4: =SUMIF('52'!D:D,Summary!$B4,'52'!E:E) -> 0 | BS4: =SUMIF('53'!D:D,Summary!$B4,'53'!E:E) -> 0
A5: =A4+1 -> 2 | B5: IDLE | D5: =S5+T5+U5+V5+W5 -> 0 | E5: =X5+Y5+Z5+AA5 -> 0 | F5: =AB5+AC5+AD5+AE5 -> 0 | G5: =AF5+AG5+AH5+AI5+AJ5 -> 0 | H5: =AK5+AL5+AM5+AN5 -> 0 | I5: =AO5+AP5+AQ5+AR5 -> #REF! | J5: =AS5+AT5+AU5+AV5+AW5 -> #REF! | K5: =AX5+AY5+AZ5+BA5 -> 0 | L5: =BB5+BC5+BD5+BE5 -> 0 | M5: =BF5+BG5+BH5+BI5+BJ5 -> 0 | N5: =BK5+BL5+BM5+BN5 -> 0 | O5: =BO5+BP5+BQ5+BR5+BS5 -> 0 | P5: =(SUM(S5:BS5)) -> #REF! | R5: =IF(Q5>P5,Q5-P5,0) -> #REF! | S5: =SUMIF('01'!D:D,Summary!$B5,'01'!E:E) -> 0 | T5: =SUMIF('02'!D:D,Summary!$B5,'02'!E:E) -> 0 | U5: =SUMIF('03'!D:D,Summary!$B5,'03'!E:E) -> 0 | V5: =SUMIF('04'!D:D,Summary!$B5,'04'!E:E) -> 0 | W5: =SUMIF('05'!D:D,Summary!$B5,'05'!E:E) -> 0 | X5: =SUMIF('06'!D:D,Summary!$B5,'06'!E:E) -> 0 | Y5: =SUMIF('07'!D:D,Summary!$B5,'07'!E:E) -> 0 | Z5: =SUMIF('08'!D:D,Summary!$B5,'08'!E:E) -> 0 | AA5: =SUMIF('09'!D:D,Summary!$B5,'09'!E:E) -> 0 | AB5: =SUMIF('10'!D:D,Summary!$B5,'10'!E:E) -> 0 | AC5: =SUMIF('11'!D:D,Summary!$B5,'11'!E:E) -> 0 | AD5: =SUMIF('12'!D:D,Summary!$B5,'12'!E:E) -> 0 | AE5: =SUMIF('13'!D:D,Summary!$B5,'13'!E:E) -> 0 | AF5: =SUMIF('14'!D:D,Summary!$B5,'14'!E:E) -> 0 | AG5: =SUMIF('15'!D:D,Summary!$B5,'15'!E:E) -> 0 | AH5: =SUMIF('16'!D:D,Summary!$B5,'16'!E:E) -> 0 | AI5: =SUMIF('17'!D:D,Summary!$B5,'17'!E:E) -> 0 | AJ5: =SUMIF('18'!D:D,Summary!$B5,'18'!E:E) -> 0 | AK5: =SUMIF('19'!D:D,Summary!$B5,'19'!E:E) -> 0 | AL5: =SUMIF('20'!D:D,Summary!$B5,'20'!E:E) -> 0 | AM5: =SUMIF('21'!D:D,Summary!$B5,'21'!E:E) -> 0 | AN5: =SUMIF('22'!D:D,Summary!$B5,'22'!$E:$E) -> 0 | AO5: =SUMIF(#REF!,Summary!$B5,#REF!) -> #REF! | AP5: =SUMIF(#REF!,Summary!$B5,#REF!) -> #REF! | AQ5: =SUMIF(#REF!,Summary!$B5,#REF!) -> #REF! | AR5: =SUMIF(#REF!,Summary!$B5,#REF!) -> #REF! | AS5: =SUMIF(#REF!,Summary!$B5,#REF!) -> #REF! | AT5: =SUMIF('28'!D:D,Summary!$B5,'28'!E:E) -> 0 | AU5: =SUMIF('29'!D:D,Summary!$B5,'29'!E:E) -> 0 | AV5: =SUMIF('30'!D:D,Summary!$B5,'30'!E:E) -> 0 | AW5: =SUMIF('31'!D:D,Summary!$B5,'31'!E:E) -> 0 | AX5: =SUMIF('32'!D:D,Summary!$B5,'32'!E:E) -> 0 | AY5: =SUMIF('33'!D:D,Summary!$B5,'33'!E:E) -> 0 | AZ5: =SUMIF('34'!D:D,Summary!$B5,'34'!E:E) -> 0 | BA5: =SUMIF('35'!D:D,Summary!$B5,'35'!E:E) -> 0 | BB5: =SUMIF('36'!D:D,Summary!$B5,'36'!E:E) -> 0 | BC5: =SUMIF('37'!D:D,Summary!$B5,'37'!E:E) -> 0 | BD5: =SUMIF('38'!D:D,Summary!$B5,'38'!E:E) -> 0 | BE5: =SUMIF('39'!D:D,Summary!$B5,'39'!E:E) -> 0 | BF5: =SUMIF('40'!D:D,Summary!$B5,'40'!E:E) -> 0 | BG5: =SUMIF('41'!D:D,Summary!$B5,'41'!E:E) -> 0 | BH5: =SUMIF('42'!D:D,Summary!$B5,'42'!E:E) -> 0 | BI5: =SUMIF('43'!D:D,Summary!$B5,'43'!E:E) -> 0 | BJ5: =SUMIF('44'!D:D,Summary!$B5,'44'!E:E) -> 0 | BK5: =SUMIF('45'!D:D,Summary!$B5,'45'!E:E) -> 0 | BL5: =SUMIF('46'!D:D,Summary!$B5,'46'!E:E) -> 0 | BM5: =SUMIF('47'!D:D,Summary!$B5,'47'!E:E) -> 0 | BN5: =SUMIF('48'!D:D,Summary!$B5,'48'!E:E) -> 0 | BO5: =SUMIF('49'!D:D,Summary!$B5,'49'!E:E) -> 0 | BP5: =SUMIF('50'!D:D,Summary!$B5,'50'!E:E) -> 0 | BQ5: =SUMIF('51'!D:D,Summary!$B5,'51'!E:E) -> 0 | BR5: =SUMIF('52'!D:D,Summary!$B5,'52'!E:E) -> 0 | BS5: =SUMIF('53'!D:D,Summary!$B5,'53'!E:E) -> 0
A6: =A5+1 -> 3 | B6: HOLIDAY | D6: =S6+T6+U6+V6+W6 -> 0 | E6: =X6+Y6+Z6+AA6 -> 0 | F6: =AB6+AC6+AD6+AE6 -> 0 | G6: =AF6+AG6+AH6+AI6+AJ6 -> 0 | H6: =AK6+AL6+AM6+AN6 -> 0 | I6: =AO6+AP6+AQ6+AR6 -> #REF! | J6: =AS6+AT6+AU6+AV6+AW6 -> #REF! | K6: =AX6+AY6+AZ6+BA6 -> 0 | L6: =BB6+BC6+BD6+BE6 -> 0 | M6: =BF6+BG6+BH6+BI6+BJ6 -> 0 | N6: =BK6+BL6+BM6+BN6 -> 0 | O6: =BO6+BP6+BQ6+BR6+BS6 -> 0 | P6: =(SUM(S6:BS6)) -> #REF! | R6: =IF(Q6>P6,Q6-P6,0) -> #REF! | S6: =SUMIF('01'!D:D,Summary!$B6,'01'!E:E) -> 0 | T6: =SUMIF('02'!D:D,Summary!$B6,'02'!E:E) -> 0 | U6: =SUMIF('03'!D:D,Summary!$B6,'03'!E:E) -> 0 | V6: =SUMIF('04'!D:D,Summary!$B6,'04'!E:E) -> 0 | W6: =SUMIF('05'!D:D,Summary!$B6,'05'!E:E) -> 0 | X6: =SUMIF('06'!D:D,Summary!$B6,'06'!E:E) -> 0 | Y6: =SUMIF('07'!D:D,Summary!$B6,'07'!E:E) -> 0 | Z6: =SUMIF('08'!D:D,Summary!$B6,'08'!E:E) -> 0 | AA6: =SUMIF('09'!D:D,Summary!$B6,'09'!E:E) -> 0 | AB6: =SUMIF('10'!D:D,Summary!$B6,'10'!E:E) -> 0 | AC6: =SUMIF('11'!D:D,Summary!$B6,'11'!E:E) -> 0 | AD6: =SUMIF('12'!D:D,Summary!$B6,'12'!E:E) -> 0 | AE6: =SUMIF('13'!D:D,Summary!$B6,'13'!E:E) -> 0 | AF6: =SUMIF('14'!D:D,Summary!$B6,'14'!E:E) -> 0 | AG6: =SUMIF('15'!D:D,Summary!$B6,'15'!E:E) -> 0 | AH6: =SUMIF('16'!D:D,Summary!$B6,'16'!E:E) -> 0 | AI6: =SUMIF('17'!D:D,Summary!$B6,'17'!E:E) -> 0 | AJ6: =SUMIF('18'!D:D,Summary!$B6,'18'!E:E) -> 0 | AK6: =SUMIF('19'!D:D,Summary!$B6,'19'!E:E) -> 0 | AL6: =SUMIF('20'!D:D,Summary!$B6,'20'!E:E) -> 0 | AM6: =SUMIF('21'!D:D,Summary!$B6,'21'!E:E) -> 0 | AN6: =SUMIF('22'!D:D,Summary!$B6,'22'!$E:$E) -> 0 | AO6: =SUMIF(#REF!,Summary!$B6,#REF!) -> #REF! | AP6: =SUMIF(#REF!,Summary!$B6,#REF!) -> #REF! | AQ6: =SUMIF(#REF!,Summary!$B6,#REF!) -> #REF! | AR6: =SUMIF(#REF!,Summary!$B6,#REF!) -> #REF! | AS6: =SUMIF(#REF!,Summary!$B6,#REF!) -> #REF! | AT6: =SUMIF('28'!D:D,Summary!$B6,'28'!E:E) -> 0 | AU6: =SUMIF('29'!D:D,Summary!$B6,'29'!E:E) -> 0 | AV6: =SUMIF('30'!D:D,Summary!$B6,'30'!E:E) -> 0 | AW6: =SUMIF('31'!D:D,Summary!$B6,'31'!E:E) -> 0 | AX6: =SUMIF('32'!D:D,Summary!$B6,'32'!E:E) -> 0 | AY6: =SUMIF('33'!D:D,Summary!$B6,'33'!E:E) -> 0 | AZ6: =SUMIF('34'!D:D,Summary!$B6,'34'!E:E) -> 0 | BA6: =SUMIF('35'!D:D,Summary!$B6,'35'!E:E) -> 0 | BB6: =SUMIF('36'!D:D,Summary!$B6,'36'!E:E) -> 0 | BC6: =SUMIF('37'!D:D,Summary!$B6,'37'!E:E) -> 0 | BD6: =SUMIF('38'!D:D,Summary!$B6,'38'!E:E) -> 0 | BE6: =SUMIF('39'!D:D,Summary!$B6,'39'!E:E) -> 0 | BF6: =SUMIF('40'!D:D,Summary!$B6,'40'!E:E) -> 0 | BG6: =SUMIF('41'!D:D,Summary!$B6,'41'!E:E) -> 0 | BH6: =SUMIF('42'!D:D,Summary!$B6,'42'!E:E) -> 0 | BI6: =SUMIF('43'!D:D,Summary!$B6,'43'!E:E) -> 0 | BJ6: =SUMIF('44'!D:D,Summary!$B6,'44'!E:E) -> 0 | BK6: =SUMIF('45'!D:D,Summary!$B6,'45'!E:E) -> 0 | BL6: =SUMIF('46'!D:D,Summary!$B6,'46'!E:E) -> 0 | BM6: =SUMIF('47'!D:D,Summary!$B6,'47'!E:E) -> 0 | BN6: =SUMIF('48'!D:D,Summary!$B6,'48'!E:E) -> 0 | BO6: =SUMIF('49'!D:D,Summary!$B6,'49'!E:E) -> 0 | BP6: =SUMIF('50'!D:D,Summary!$B6,'50'!E:E) -> 0 | BQ6: =SUMIF('51'!D:D,Summary!$B6,'51'!E:E) -> 0 | BR6: =SUMIF('52'!D:D,Summary!$B6,'52'!E:E) -> 0 | BS6: =SUMIF('53'!D:D,Summary!$B6,'53'!E:E) -> 0
A7: =A6+1 -> 4 | B7: FA215 | D7: =S7+T7+U7+V7+W7 -> 0 | E7: =X7+Y7+Z7+AA7 -> 0 | F7: =AB7+AC7+AD7+AE7 -> 0 | G7: =AF7+AG7+AH7+AI7+AJ7 -> 0 | H7: =AK7+AL7+AM7+AN7 -> 0 | I7: =AO7+AP7+AQ7+AR7 -> #REF! | J7: =AS7+AT7+AU7+AV7+AW7 -> #REF! | K7: =AX7+AY7+AZ7+BA7 -> 0 | L7: =BB7+BC7+BD7+BE7 -> 0 | M7: =BF7+BG7+BH7+BI7+BJ7 -> 0 | N7: =BK7+BL7+BM7+BN7 -> 0 | O7: =BO7+BP7+BQ7+BR7+BS7 -> 0 | P7: =(SUM(S7:BS7)) -> #REF! | R7: =IF(Q7>P7,Q7-P7,0) -> #REF! | S7: =SUMIF('01'!D:D,Summary!$B7,'01'!E:E) -> 0 | T7: =SUMIF('02'!D:D,Summary!$B7,'02'!E:E) -> 0 | U7: =SUMIF('03'!D:D,Summary!$B7,'03'!E:E) -> 0 | V7: =SUMIF('04'!D:D,Summary!$B7,'04'!E:E) -> 0 | W7: =SUMIF('05'!D:D,Summary!$B7,'05'!E:E) -> 0 | X7: =SUMIF('06'!D:D,Summary!$B7,'06'!E:E) -> 0 | Y7: =SUMIF('07'!D:D,Summary!$B7,'07'!E:E) -> 0 | Z7: =SUMIF('08'!D:D,Summary!$B7,'08'!E:E) -> 0 | AA7: =SUMIF('09'!D:D,Summary!$B7,'09'!E:E) -> 0 | AB7: =SUMIF('10'!D:D,Summary!$B7,'10'!E:E) -> 0 | AC7: =SUMIF('11'!D:D,Summary!$B7,'11'!E:E) -> 0 | AD7: =SUMIF('12'!D:D,Summary!$B7,'12'!E:E) -> 0 | AE7: =SUMIF('13'!D:D,Summary!$B7,'13'!E:E) -> 0 | AF7: =SUMIF('14'!D:D,Summary!$B7,'14'!E:E) -> 0 | AG7: =SUMIF('15'!D:D,Summary!$B7,'15'!E:E) -> 0 | AH7: =SUMIF('16'!D:D,Summary!$B7,'16'!E:E) -> 0 | AI7: =SUMIF('17'!D:D,Summary!$B7,'17'!E:E) -> 0 | AJ7: =SUMIF('18'!D:D,Summary!$B7,'18'!E:E) -> 0 | AK7: =SUMIF('19'!D:D,Summary!$B7,'19'!E:E) -> 0 | AL7: =SUMIF('20'!D:D,Summary!$B7,'20'!E:E) -> 0 | AM7: =SUMIF('21'!D:D,Summary!$B7,'21'!E:E) -> 0 | AN7: =SUMIF('22'!D:D,Summary!$B7,'22'!$E:$E) -> 0 | AO7: =SUMIF(#REF!,Summary!$B7,#REF!) -> #REF! | AP7: =SUMIF(#REF!,Summary!$B7,#REF!) -> #REF! | AQ7: =SUMIF(#REF!,Summary!$B7,#REF!) -> #REF! | AR7: =SUMIF(#REF!,Summary!$B7,#REF!) -> #REF! | AS7: =SUMIF(#REF!,Summary!$B7,#REF!) -> #REF! | AT7: =SUMIF('28'!D:D,Summary!$B7,'28'!E:E) -> 0 | AU7: =SUMIF('29'!D:D,Summary!$B7,'29'!E:E) -> 0 | AV7: =SUMIF('30'!D:D,Summary!$B7,'30'!E:E) -> 0 | AW7: =SUMIF('31'!D:D,Summary!$B7,'31'!E:E) -> 0 | AX7: =SUMIF('32'!D:D,Summary!$B7,'32'!E:E) -> 0 | AY7: =SUMIF('33'!D:D,Summary!$B7,'33'!E:E) -> 0 | AZ7: =SUMIF('34'!D:D,Summary!$B7,'34'!E:E) -> 0 | BA7: =SUMIF('35'!D:D,Summary!$B7,'35'!E:E) -> 0 | BB7: =SUMIF('36'!D:D,Summary!$B7,'36'!E:E) -> 0 | BC7: =SUMIF('37'!D:D,Summary!$B7,'37'!E:E) -> 0 | BD7: =SUMIF('38'!D:D,Summary!$B7,'38'!E:E) -> 0 | BE7: =SUMIF('39'!D:D,Summary!$B7,'39'!E:E) -> 0 | BF7: =SUMIF('40'!D:D,Summary!$B7,'40'!E:E) -> 0 | BG7: =SUMIF('41'!D:D,Summary!$B7,'41'!E:E) -> 0 | BH7: =SUMIF('42'!D:D,Summary!$B7,'42'!E:E) -> 0 | BI7: =SUMIF('43'!D:D,Summary!$B7,'43'!E:E) -> 0 | BJ7: =SUMIF('44'!D:D,Summary!$B7,'44'!E:E) -> 0 | BK7: =SUMIF('45'!D:D,Summary!$B7,'45'!E:E) -> 0 | BL7: =SUMIF('46'!D:D,Summary!$B7,'46'!E:E) -> 0 | BM7: =SUMIF('47'!D:D,Summary!$B7,'47'!E:E) -> 0 | BN7: =SUMIF('48'!D:D,Summary!$B7,'48'!E:E) -> 0 | BO7: =SUMIF('49'!D:D,Summary!$B7,'49'!E:E) -> 0 | BP7: =SUMIF('50'!D:D,Summary!$B7,'50'!E:E) -> 0 | BQ7: =SUMIF('51'!D:D,Summary!$B7,'51'!E:E) -> 0 | BR7: =SUMIF('52'!D:D,Summary!$B7,'52'!E:E) -> 0 | BS7: =SUMIF('53'!D:D,Summary!$B7,'53'!E:E) -> 0
A8: =A7+1 -> 5 | B8: FA229 | D8: =S8+T8+U8+V8+W8 -> 0 | E8: =X8+Y8+Z8+AA8 -> 0 | F8: =AB8+AC8+AD8+AE8 -> 0 | G8: =AF8+AG8+AH8+AI8+AJ8 -> 0 | H8: =AK8+AL8+AM8+AN8 -> 0 | I8: =AO8+AP8+AQ8+AR8 -> #REF! | J8: =AS8+AT8+AU8+AV8+AW8 -> #REF! | K8: =AX8+AY8+AZ8+BA8 -> 0 | L8: =BB8+BC8+BD8+BE8 -> 0 | M8: =BF8+BG8+BH8+BI8+BJ8 -> 0 | N8: =BK8+BL8+BM8+BN8 -> 0 | O8: =BO8+BP8+BQ8+BR8+BS8 -> 0 | P8: =(SUM(S8:BS8)) -> #REF! | R8: =IF(Q8>P8,Q8-P8,0) -> #REF! | S8: =SUMIF('01'!D:D,Summary!$B8,'01'!E:E) -> 0 | T8: =SUMIF('02'!D:D,Summary!$B8,'02'!E:E) -> 0 | U8: =SUMIF('03'!D:D,Summary!$B8,'03'!E:E) -> 0 | V8: =SUMIF('04'!D:D,Summary!$B8,'04'!E:E) -> 0 | W8: =SUMIF('05'!D:D,Summary!$B8,'05'!E:E) -> 0 | X8: =SUMIF('06'!D:D,Summary!$B8,'06'!E:E) -> 0 | Y8: =SUMIF('07'!D:D,Summary!$B8,'07'!E:E) -> 0 | Z8: =SUMIF('08'!D:D,Summary!$B8,'08'!E:E) -> 0 | AA8: =SUMIF('09'!D:D,Summary!$B8,'09'!E:E) -> 0 | AB8: =SUMIF('10'!D:D,Summary!$B8,'10'!E:E) -> 0 | AC8: =SUMIF('11'!D:D,Summary!$B8,'11'!E:E) -> 0 | AD8: =SUMIF('12'!D:D,Summary!$B8,'12'!E:E) -> 0 | AE8: =SUMIF('13'!D:D,Summary!$B8,'13'!E:E) -> 0 | AF8: =SUMIF('14'!D:D,Summary!$B8,'14'!E:E) -> 0 | AG8: =SUMIF('15'!D:D,Summary!$B8,'15'!E:E) -> 0 | AH8: =SUMIF('16'!D:D,Summary!$B8,'16'!E:E) -> 0 | AI8: =SUMIF('17'!D:D,Summary!$B8,'17'!E:E) -> 0 | AJ8: =SUMIF('18'!D:D,Summary!$B8,'18'!E:E) -> 0 | AK8: =SUMIF('19'!D:D,Summary!$B8,'19'!E:E) -> 0 | AL8: =SUMIF('20'!D:D,Summary!$B8,'20'!E:E) -> 0 | AM8: =SUMIF('21'!D:D,Summary!$B8,'21'!E:E) -> 0 | AN8: =SUMIF('22'!D:D,Summary!$B8,'22'!$E:$E) -> 0 | AO8: =SUMIF(#REF!,Summary!$B8,#REF!) -> #REF! | AP8: =SUMIF(#REF!,Summary!$B8,#REF!) -> #REF! | AQ8: =SUMIF(#REF!,Summary!$B8,#REF!) -> #REF! | AR8: =SUMIF(#REF!,Summary!$B8,#REF!) -> #REF! | AS8: =SUMIF(#REF!,Summary!$B8,#REF!) -> #REF! | AT8: =SUMIF('28'!D:D,Summary!$B8,'28'!E:E) -> 0 | AU8: =SUMIF('29'!D:D,Summary!$B8,'29'!E:E) -> 0 | AV8: =SUMIF('30'!D:D,Summary!$B8,'30'!E:E) -> 0 | AW8: =SUMIF('31'!D:D,Summary!$B8,'31'!E:E) -> 0 | AX8: =SUMIF('32'!D:D,Summary!$B8,'32'!E:E) -> 0 | AY8: =SUMIF('33'!D:D,Summary!$B8,'33'!E:E) -> 0 | AZ8: =SUMIF('34'!D:D,Summary!$B8,'34'!E:E) -> 0 | BA8: =SUMIF('35'!D:D,Summary!$B8,'35'!E:E) -> 0 | BB8: =SUMIF('36'!D:D,Summary!$B8,'36'!E:E) -> 0 | BC8: =SUMIF('37'!D:D,Summary!$B8,'37'!E:E) -> 0 | BD8: =SUMIF('38'!D:D,Summary!$B8,'38'!E:E) -> 0 | BE8: =SUMIF('39'!D:D,Summary!$B8,'39'!E:E) -> 0 | BF8: =SUMIF('40'!D:D,Summary!$B8,'40'!E:E) -> 0 | BG8: =SUMIF('41'!D:D,Summary!$B8,'41'!E:E) -> 0 | BH8: =SUMIF('42'!D:D,Summary!$B8,'42'!E:E) -> 0 | BI8: =SUMIF('43'!D:D,Summary!$B8,'43'!E:E) -> 0 | BJ8: =SUMIF('44'!D:D,Summary!$B8,'44'!E:E) -> 0 | BK8: =SUMIF('45'!D:D,Summary!$B8,'45'!E:E) -> 0 | BL8: =SUMIF('46'!D:D,Summary!$B8,'46'!E:E) -> 0 | BM8: =SUMIF('47'!D:D,Summary!$B8,'47'!E:E) -> 0 | BN8: =SUMIF('48'!D:D,Summary!$B8,'48'!E:E) -> 0 | BO8: =SUMIF('49'!D:D,Summary!$B8,'49'!E:E) -> 0 | BP8: =SUMIF('50'!D:D,Summary!$B8,'50'!E:E) -> 0 | BQ8: =SUMIF('51'!D:D,Summary!$B8,'51'!E:E) -> 0 | BR8: =SUMIF('52'!D:D,Summary!$B8,'52'!E:E) -> 0 | BS8: =SUMIF('53'!D:D,Summary!$B8,'53'!E:E) -> 0
A9: =A8+1 -> 6 | B9: FA232 | D9: =S9+T9+U9+V9+W9 -> 0 | E9: =X9+Y9+Z9+AA9 -> 0 | F9: =AB9+AC9+AD9+AE9 -> 0 | G9: =AF9+AG9+AH9+AI9+AJ9 -> 0 | H9: =AK9+AL9+AM9+AN9 -> 0 | I9: =AO9+AP9+AQ9+AR9 -> #REF! | J9: =AS9+AT9+AU9+AV9+AW9 -> #REF! | K9: =AX9+AY9+AZ9+BA9 -> 0 | L9: =BB9+BC9+BD9+BE9 -> 0 | M9: =BF9+BG9+BH9+BI9+BJ9 -> 0 | N9: =BK9+BL9+BM9+BN9 -> 0 | O9: =BO9+BP9+BQ9+BR9+BS9 -> 0 | P9: =(SUM(S9:BS9)) -> #REF! | R9: =IF(Q9>P9,Q9-P9,0) -> #REF! | S9: =SUMIF('01'!D:D,Summary!$B9,'01'!E:E) -> 0 | T9: =SUMIF('02'!D:D,Summary!$B9,'02'!E:E) -> 0 | U9: =SUMIF('03'!D:D,Summary!$B9,'03'!E:E) -> 0 | V9: =SUMIF('04'!D:D,Summary!$B9,'04'!E:E) -> 0 | W9: =SUMIF('05'!D:D,Summary!$B9,'05'!E:E) -> 0 | X9: =SUMIF('06'!D:D,Summary!$B9,'06'!E:E) -> 0 | Y9: =SUMIF('07'!D:D,Summary!$B9,'07'!E:E) -> 0 | Z9: =SUMIF('08'!D:D,Summary!$B9,'08'!E:E) -> 0 | AA9: =SUMIF('09'!D:D,Summary!$B9,'09'!E:E) -> 0 | AB9: =SUMIF('10'!D:D,Summary!$B9,'10'!E:E) -> 0 | AC9: =SUMIF('11'!D:D,Summary!$B9,'11'!E:E) -> 0 | AD9: =SUMIF('12'!D:D,Summary!$B9,'12'!E:E) -> 0 | AE9: =SUMIF('13'!D:D,Summary!$B9,'13'!E:E) -> 0 | AF9: =SUMIF('14'!D:D,Summary!$B9,'14'!E:E) -> 0 | AG9: =SUMIF('15'!D:D,Summary!$B9,'15'!E:E) -> 0 | AH9: =SUMIF('16'!D:D,Summary!$B9,'16'!E:E) -> 0 | AI9: =SUMIF('17'!D:D,Summary!$B9,'17'!E:E) -> 0 | AJ9: =SUMIF('18'!D:D,Summary!$B9,'18'!E:E) -> 0 | AK9: =SUMIF('19'!D:D,Summary!$B9,'19'!E:E) -> 0 | AL9: =SUMIF('20'!D:D,Summary!$B9,'20'!E:E) -> 0 | AM9: =SUMIF('21'!D:D,Summary!$B9,'21'!E:E) -> 0 | AN9: =SUMIF('22'!D:D,Summary!$B9,'22'!$E:$E) -> 0 | AO9: =SUMIF(#REF!,Summary!$B9,#REF!) -> #REF! | AP9: =SUMIF(#REF!,Summary!$B9,#REF!) -> #REF! | AQ9: =SUMIF(#REF!,Summary!$B9,#REF!) -> #REF! | AR9: =SUMIF(#REF!,Summary!$B9,#REF!) -> #REF! | AS9: =SUMIF(#REF!,Summary!$B9,#REF!) -> #REF! | AT9: =SUMIF('28'!D:D,Summary!$B9,'28'!E:E) -> 0 | AU9: =SUMIF('29'!D:D,Summary!$B9,'29'!E:E) -> 0 | AV9: =SUMIF('30'!D:D,Summary!$B9,'30'!E:E) -> 0 | AW9: =SUMIF('31'!D:D,Summary!$B9,'31'!E:E) -> 0 | AX9: =SUMIF('32'!D:D,Summary!$B9,'32'!E:E) -> 0 | AY9: =SUMIF('33'!D:D,Summary!$B9,'33'!E:E) -> 0 | AZ9: =SUMIF('34'!D:D,Summary!$B9,'34'!E:E) -> 0 | BA9: =SUMIF('35'!D:D,Summary!$B9,'35'!E:E) -> 0 | BB9: =SUMIF('36'!D:D,Summary!$B9,'36'!E:E) -> 0 | BC9: =SUMIF('37'!D:D,Summary!$B9,'37'!E:E) -> 0 | BD9: =SUMIF('38'!D:D,Summary!$B9,'38'!E:E) -> 0 | BE9: =SUMIF('39'!D:D,Summary!$B9,'39'!E:E) -> 0 | BF9: =SUMIF('40'!D:D,Summary!$B9,'40'!E:E) -> 0 | BG9: =SUMIF('41'!D:D,Summary!$B9,'41'!E:E) -> 0 | BH9: =SUMIF('42'!D:D,Summary!$B9,'42'!E:E) -> 0 | BI9: =SUMIF('43'!D:D,Summary!$B9,'43'!E:E) -> 0 | BJ9: =SUMIF('44'!D:D,Summary!$B9,'44'!E:E) -> 0 | BK9: =SUMIF('45'!D:D,Summary!$B9,'45'!E:E) -> 0 | BL9: =SUMIF('46'!D:D,Summary!$B9,'46'!E:E) -> 0 | BM9: =SUMIF('47'!D:D,Summary!$B9,'47'!E:E) -> 0 | BN9: =SUMIF('48'!D:D,Summary!$B9,'48'!E:E) -> 0 | BO9: =SUMIF('49'!D:D,Summary!$B9,'49'!E:E) -> 0 | BP9: =SUMIF('50'!D:D,Summary!$B9,'50'!E:E) -> 0 | BQ9: =SUMIF('51'!D:D,Summary!$B9,'51'!E:E) -> 0 | BR9: =SUMIF('52'!D:D,Summary!$B9,'52'!E:E) -> 0 | BS9: =SUMIF('53'!D:D,Summary!$B9,'53'!E:E) -> 0
A10: =A9+1 -> 7 | B10: FA236 | D10: =S10+T10+U10+V10+W10 -> 0 | E10: =X10+Y10+Z10+AA10 -> 0 | F10: =AB10+AC10+AD10+AE10 -> 0 | G10: =AF10+AG10+AH10+AI10+AJ10 -> 0 | H10: =AK10+AL10+AM10+AN10 -> 0 | I10: =AO10+AP10+AQ10+AR10 -> #REF! | J10: =AS10+AT10+AU10+AV10+AW10 -> #REF! | K10: =AX10+AY10+AZ10+BA10 -> 0 | L10: =BB10+BC10+BD10+BE10 -> 0 | M10: =BF10+BG10+BH10+BI10+BJ10 -> 0 | N10: =BK10+BL10+BM10+BN10 -> 0 | O10: =BO10+BP10+BQ10+BR10+BS10 -> 0 | P10: =(SUM(S10:BS10)) -> #REF! | R10: =IF(Q10>P10,Q10-P10,0) -> #REF! | S10: =SUMIF('01'!D:D,Summary!$B10,'01'!E:E) -> 0 | T10: =SUMIF('02'!D:D,Summary!$B10,'02'!E:E) -> 0 | U10: =SUMIF('03'!D:D,Summary!$B10,'03'!E:E) -> 0 | V10: =SUMIF('04'!D:D,Summary!$B10,'04'!E:E) -> 0 | W10: =SUMIF('05'!D:D,Summary!$B10,'05'!E:E) -> 0 | X10: =SUMIF('06'!D:D,Summary!$B10,'06'!E:E) -> 0 | Y10: =SUMIF('07'!D:D,Summary!$B10,'07'!E:E) -> 0 | Z10: =SUMIF('08'!D:D,Summary!$B10,'08'!E:E) -> 0 | AA10: =SUMIF('09'!D:D,Summary!$B10,'09'!E:E) -> 0 | AB10: =SUMIF('10'!D:D,Summary!$B10,'10'!E:E) -> 0 | AC10: =SUMIF('11'!D:D,Summary!$B10,'11'!E:E) -> 0 | AD10: =SUMIF('12'!D:D,Summary!$B10,'12'!E:E) -> 0 | AE10: =SUMIF('13'!D:D,Summary!$B10,'13'!E:E) -> 0 | AF10: =SUMIF('14'!D:D,Summary!$B10,'14'!E:E) -> 0 | AG10: =SUMIF('15'!D:D,Summary!$B10,'15'!E:E) -> 0 | AH10: =SUMIF('16'!D:D,Summary!$B10,'16'!E:E) -> 0 | AI10: =SUMIF('17'!D:D,Summary!$B10,'17'!E:E) -> 0 | AJ10: =SUMIF('18'!D:D,Summary!$B10,'18'!E:E) -> 0 | AK10: =SUMIF('19'!D:D,Summary!$B10,'19'!E:E) -> 0 | AL10: =SUMIF('20'!D:D,Summary!$B10,'20'!E:E) -> 0 | AM10: =SUMIF('21'!D:D,Summary!$B10,'21'!E:E) -> 0 | AN10: =SUMIF('22'!D:D,Summary!$B10,'22'!$E:$E) -> 0 | AO10: =SUMIF(#REF!,Summary!$B10,#REF!) -> #REF! | AP10: =SUMIF(#REF!,Summary!$B10,#REF!) -> #REF! | AQ10: =SUMIF(#REF!,Summary!$B10,#REF!) -> #REF! | AR10: =SUMIF(#REF!,Summary!$B10,#REF!) -> #REF! | AS10: =SUMIF(#REF!,Summary!$B10,#REF!) -> #REF! | AT10: =SUMIF('28'!D:D,Summary!$B10,'28'!E:E) -> 0 | AU10: =SUMIF('29'!D:D,Summary!$B10,'29'!E:E) -> 0 | AV10: =SUMIF('30'!D:D,Summary!$B10,'30'!E:E) -> 0 | AW10: =SUMIF('31'!D:D,Summary!$B10,'31'!E:E) -> 0 | AX10: =SUMIF('32'!D:D,Summary!$B10,'32'!E:E) -> 0 | AY10: =SUMIF('33'!D:D,Summary!$B10,'33'!E:E) -> 0 | AZ10: =SUMIF('34'!D:D,Summary!$B10,'34'!E:E) -> 0 | BA10: =SUMIF('35'!D:D,Summary!$B10,'35'!E:E) -> 0 | BB10: =SUMIF('36'!D:D,Summary!$B10,'36'!E:E) -> 0 | BC10: =SUMIF('37'!D:D,Summary!$B10,'37'!E:E) -> 0 | BD10: =SUMIF('38'!D:D,Summary!$B10,'38'!E:E) -> 0 | BE10: =SUMIF('39'!D:D,Summary!$B10,'39'!E:E) -> 0 | BF10: =SUMIF('40'!D:D,Summary!$B10,'40'!E:E) -> 0 | BG10: =SUMIF('41'!D:D,Summary!$B10,'41'!E:E) -> 0 | BH10: =SUMIF('42'!D:D,Summary!$B10,'42'!E:E) -> 0 | BI10: =SUMIF('43'!D:D,Summary!$B10,'43'!E:E) -> 0 | BJ10: =SUMIF('44'!D:D,Summary!$B10,'44'!E:E) -> 0 | BK10: =SUMIF('45'!D:D,Summary!$B10,'45'!E:E) -> 0 | BL10: =SUMIF('46'!D:D,Summary!$B10,'46'!E:E) -> 0 | BM10: =SUMIF('47'!D:D,Summary!$B10,'47'!E:E) -> 0 | BN10: =SUMIF('48'!D:D,Summary!$B10,'48'!E:E) -> 0 | BO10: =SUMIF('49'!D:D,Summary!$B10,'49'!E:E) -> 0 | BP10: =SUMIF('50'!D:D,Summary!$B10,'50'!E:E) -> 0 | BQ10: =SUMIF('51'!D:D,Summary!$B10,'51'!E:E) -> 0 | BR10: =SUMIF('52'!D:D,Summary!$B10,'52'!E:E) -> 0 | BS10: =SUMIF('53'!D:D,Summary!$B10,'53'!E:E) -> 0
A11: =A10+1 -> 8 | B11: FA238 | D11: =S11+T11+U11+V11+W11 -> 384 | E11: =X11+Y11+Z11+AA11 -> 344 | F11: =AB11+AC11+AD11+AE11 -> 96 | G11: =AF11+AG11+AH11+AI11+AJ11 -> 0 | H11: =AK11+AL11+AM11+AN11 -> 240 | I11: =AO11+AP11+AQ11+AR11 -> #REF! | J11: =AS11+AT11+AU11+AV11+AW11 -> #REF! | K11: =AX11+AY11+AZ11+BA11 -> 0 | L11: =BB11+BC11+BD11+BE11 -> 0 | M11: =BF11+BG11+BH11+BI11+BJ11 -> 0 | N11: =BK11+BL11+BM11+BN11 -> 0 | O11: =BO11+BP11+BQ11+BR11+BS11 -> 0 | P11: =(SUM(S11:BS11)) -> #REF! | R11: =IF(Q11>P11,Q11-P11,0) -> #REF! | S11: =SUMIF('01'!D:D,Summary!$B11,'01'!E:E) -> 40 | T11: =SUMIF('02'!D:D,Summary!$B11,'02'!E:E) -> 88 | U11: =SUMIF('03'!D:D,Summary!$B11,'03'!E:E) -> 136 | V11: =SUMIF('04'!D:D,Summary!$B11,'04'!E:E) -> 88 | W11: =SUMIF('05'!D:D,Summary!$B11,'05'!E:E) -> 32 | X11: =SUMIF('06'!D:D,Summary!$B11,'06'!E:E) -> 96 | Y11: =SUMIF('07'!D:D,Summary!$B11,'07'!E:E) -> 96 | Z11: =SUMIF('08'!D:D,Summary!$B11,'08'!E:E) -> 96 | AA11: =SUMIF('09'!D:D,Summary!$B11,'09'!E:E) -> 56 | AB11: =SUMIF('10'!D:D,Summary!$B11,'10'!E:E) -> 48 | AC11: =SUMIF('11'!D:D,Summary!$B11,'11'!E:E) -> 48 | AD11: =SUMIF('12'!D:D,Summary!$B11,'12'!E:E) -> 0 | AE11: =SUMIF('13'!D:D,Summary!$B11,'13'!E:E) -> 0 | AF11: =SUMIF('14'!D:D,Summary!$B11,'14'!E:E) -> 0 | AG11: =SUMIF('15'!D:D,Summary!$B11,'15'!E:E) -> 0 | AH11: =SUMIF('16'!D:D,Summary!$B11,'16'!E:E) -> 0 | AI11: =SUMIF('17'!D:D,Summary!$B11,'17'!E:E) -> 0 | AJ11: =SUMIF('18'!D:D,Summary!$B11,'18'!E:E) -> 0 | AK11: =SUMIF('19'!D:D,Summary!$B11,'19'!E:E) -> 48 | AL11: =SUMIF('20'!D:D,Summary!$B11,'20'!E:E) -> 48 | AM11: =SUMIF('21'!D:D,Summary!$B11,'21'!E:E) -> 48 | AN11: =SUMIF('22'!D:D,Summary!$B11,'22'!$E:$E) -> 96 | AO11: =SUMIF(#REF!,Summary!$B11,#REF!) -> #REF! | AP11: =SUMIF(#REF!,Summary!$B11,#REF!) -> #REF! | AQ11: =SUMIF(#REF!,Summary!$B11,#REF!) -> #REF! | AR11: =SUMIF(#REF!,Summary!$B11,#REF!) -> #REF! | AS11: =SUMIF(#REF!,Summary!$B11,#REF!) -> #REF! | AT11: =SUMIF('28'!D:D,Summary!$B11,'28'!E:E) -> 0 | AU11: =SUMIF('29'!D:D,Summary!$B11,'29'!E:E) -> 0 | AV11: =SUMIF('30'!D:D,Summary!$B11,'30'!E:E) -> 0 | AW11: =SUMIF('31'!D:D,Summary!$B11,'31'!E:E) -> 0 | AX11: =SUMIF('32'!D:D,Summary!$B11,'32'!E:E) -> 0 | AY11: =SUMIF('33'!D:D,Summary!$B11,'33'!E:E) -> 0 | AZ11: =SUMIF('34'!D:D,Summary!$B11,'34'!E:E) -> 0 | BA11: =SUMIF('35'!D:D,Summary!$B11,'35'!E:E) -> 0 | BB11: =SUMIF('36'!D:D,Summary!$B11,'36'!E:E) -> 0 | BC11: =SUMIF('37'!D:D,Summary!$B11,'37'!E:E) -> 0 | BD11: =SUMIF('38'!D:D,Summary!$B11,'38'!E:E) -> 0 | BE11: =SUMIF('39'!D:D,Summary!$B11,'39'!E:E) -> 0 | BF11: =SUMIF('40'!D:D,Summary!$B11,'40'!E:E) -> 0 | BG11: =SUMIF('41'!D:D,Summary!$B11,'41'!E:E) -> 0 | BH11: =SUMIF('42'!D:D,Summary!$B11,'42'!E:E) -> 0 | BI11: =SUMIF('43'!D:D,Summary!$B11,'43'!E:E) -> 0 | BJ11: =SUMIF('44'!D:D,Summary!$B11,'44'!E:E) -> 0 | BK11: =SUMIF('45'!D:D,Summary!$B11,'45'!E:E) -> 0 | BL11: =SUMIF('46'!D:D,Summary!$B11,'46'!E:E) -> 0 | BM11: =SUMIF('47'!D:D,Summary!$B11,'47'!E:E) -> 0 | BN11: =SUMIF('48'!D:D,Summary!$B11,'48'!E:E) -> 0 | BO11: =SUMIF('49'!D:D,Summary!$B11,'49'!E:E) -> 0 | BP11: =SUMIF('50'!D:D,Summary!$B11,'50'!E:E) -> 0 | BQ11: =SUMIF('51'!D:D,Summary!$B11,'51'!E:E) -> 0 | BR11: =SUMIF('52'!D:D,Summary!$B11,'52'!E:E) -> 0 | BS11: =SUMIF('53'!D:D,Summary!$B11,'53'!E:E) -> 0
A12: =A11+1 -> 9 | B12: FA240 | D12: =S12+T12+U12+V12+W12 -> 0 | E12: =X12+Y12+Z12+AA12 -> 200 | F12: =AB12+AC12+AD12+AE12 -> 96 | G12: =AF12+AG12+AH12+AI12+AJ12 -> 0 | H12: =AK12+AL12+AM12+AN12 -> 0 | I12: =AO12+AP12+AQ12+AR12 -> #REF! | J12: =AS12+AT12+AU12+AV12+AW12 -> #REF! | K12: =AX12+AY12+AZ12+BA12 -> 0 | L12: =BB12+BC12+BD12+BE12 -> 0 | M12: =BF12+BG12+BH12+BI12+BJ12 -> 0 | N12: =BK12+BL12+BM12+BN12 -> 0 | O12: =BO12+BP12+BQ12+BR12+BS12 -> 0 | P12: =(SUM(S12:BS12)) -> #REF! | R12: =IF(Q12>P12,Q12-P12,0) -> #REF! | S12: =SUMIF('01'!D:D,Summary!$B12,'01'!E:E) -> 0 | T12: =SUMIF('02'!D:D,Summary!$B12,'02'!E:E) -> 0 | U12: =SUMIF('03'!D:D,Summary!$B12,'03'!E:E) -> 0 | V12: =SUMIF('04'!D:D,Summary!$B12,'04'!E:E) -> 0 | W12: =SUMIF('05'!D:D,Summary!$B12,'05'!E:E) -> 0 | X12: =SUMIF('06'!D:D,Summary!$B12,'06'!E:E) -> 48 | Y12: =SUMIF('07'!D:D,Summary!$B12,'07'!E:E) -> 48 | Z12: =SUMIF('08'!D:D,Summary!$B12,'08'!E:E) -> 48 | AA12: =SUMIF('09'!D:D,Summary!$B12,'09'!E:E) -> 56 | AB12: =SUMIF('10'!D:D,Summary!$B12,'10'!E:E) -> 48 | AC12: =SUMIF('11'!D:D,Summary!$B12,'11'!E:E) -> 48 | AD12: =SUMIF('12'!D:D,Summary!$B12,'12'!E:E) -> 0 | AE12: =SUMIF('13'!D:D,Summary!$B12,'13'!E:E) -> 0 | AF12: =SUMIF('14'!D:D,Summary!$B12,'14'!E:E) -> 0 | AG12: =SUMIF('15'!D:D,Summary!$B12,'15'!E:E) -> 0 | AH12: =SUMIF('16'!D:D,Summary!$B12,'16'!E:E) -> 0 | AI12: =SUMIF('17'!D:D,Summary!$B12,'17'!E:E) -> 0 | AJ12: =SUMIF('18'!D:D,Summary!$B12,'18'!E:E) -> 0 | AK12: =SUMIF('19'!D:D,Summary!$B12,'19'!E:E) -> 0 | AL12: =SUMIF('20'!D:D,Summary!$B12,'20'!E:E) -> 0 | AM12: =SUMIF('21'!D:D,Summary!$B12,'21'!E:E) -> 0 | AN12: =SUMIF('22'!D:D,Summary!$B12,'22'!$E:$E) -> 0 | AO12: =SUMIF(#REF!,Summary!$B12,#REF!) -> #REF! | AP12: =SUMIF(#REF!,Summary!$B12,#REF!) -> #REF! | AQ12: =SUMIF(#REF!,Summary!$B12,#REF!) -> #REF! | AR12: =SUMIF(#REF!,Summary!$B12,#REF!) -> #REF! | AS12: =SUMIF(#REF!,Summary!$B12,#REF!) -> #REF! | AT12: =SUMIF('28'!D:D,Summary!$B12,'28'!E:E) -> 0 | AU12: =SUMIF('29'!D:D,Summary!$B12,'29'!E:E) -> 0 | AV12: =SUMIF('30'!D:D,Summary!$B12,'30'!E:E) -> 0 | AW12: =SUMIF('31'!D:D,Summary!$B12,'31'!E:E) -> 0 | AX12: =SUMIF('32'!D:D,Summary!$B12,'32'!E:E) -> 0 | AY12: =SUMIF('33'!D:D,Summary!$B12,'33'!E:E) -> 0 | AZ12: =SUMIF('34'!D:D,Summary!$B12,'34'!E:E) -> 0 | BA12: =SUMIF('35'!D:D,Summary!$B12,'35'!E:E) -> 0 | BB12: =SUMIF('36'!D:D,Summary!$B12,'36'!E:E) -> 0 | BC12: =SUMIF('37'!D:D,Summary!$B12,'37'!E:E) -> 0 | BD12: =SUMIF('38'!D:D,Summary!$B12,'38'!E:E) -> 0 | BE12: =SUMIF('39'!D:D,Summary!$B12,'39'!E:E) -> 0 | BF12: =SUMIF('40'!D:D,Summary!$B12,'40'!E:E) -> 0 | BG12: =SUMIF('41'!D:D,Summary!$B12,'41'!E:E) -> 0 | BH12: =SUMIF('42'!D:D,Summary!$B12,'42'!E:E) -> 0 | BI12: =SUMIF('43'!D:D,Summary!$B12,'43'!E:E) -> 0 | BJ12: =SUMIF('44'!D:D,Summary!$B12,'44'!E:E) -> 0 | BK12: =SUMIF('45'!D:D,Summary!$B12,'45'!E:E) -> 0 | BL12: =SUMIF('46'!D:D,Summary!$B12,'46'!E:E) -> 0 | BM12: =SUMIF('47'!D:D,Summary!$B12,'47'!E:E) -> 0 | BN12: =SUMIF('48'!D:D,Summary!$B12,'48'!E:E) -> 0 | BO12: =SUMIF('49'!D:D,Summary!$B12,'49'!E:E) -> 0 | BP12: =SUMIF('50'!D:D,Summary!$B12,'50'!E:E) -> 0 | BQ12: =SUMIF('51'!D:D,Summary!$B12,'51'!E:E) -> 0 | BR12: =SUMIF('52'!D:D,Summary!$B12,'52'!E:E) -> 0 | BS12: =SUMIF('53'!D:D,Summary!$B12,'53'!E:E) -> 0
A13: =A12+1 -> 10 | B13: FA241 | D13: =S13+T13+U13+V13+W13 -> 328 | E13: =X13+Y13+Z13+AA13 -> 392 | F13: =AB13+AC13+AD13+AE13 -> 96 | G13: =AF13+AG13+AH13+AI13+AJ13 -> 0 | H13: =AK13+AL13+AM13+AN13 -> 0 | I13: =AO13+AP13+AQ13+AR13 -> #REF! | J13: =AS13+AT13+AU13+AV13+AW13 -> #REF! | K13: =AX13+AY13+AZ13+BA13 -> 0 | L13: =BB13+BC13+BD13+BE13 -> 0 | M13: =BF13+BG13+BH13+BI13+BJ13 -> 0 | N13: =BK13+BL13+BM13+BN13 -> 0 | O13: =BO13+BP13+BQ13+BR13+BS13 -> 0 | P13: =(SUM(S13:BS13)) -> #REF! | R13: =IF(Q13>P13,Q13-P13,0) -> #REF! | S13: =SUMIF('01'!D:D,Summary!$B13,'01'!E:E) -> 48 | T13: =SUMIF('02'!D:D,Summary!$B13,'02'!E:E) -> 96 | U13: =SUMIF('03'!D:D,Summary!$B13,'03'!E:E) -> 96 | V13: =SUMIF('04'!D:D,Summary!$B13,'04'!E:E) -> 48 | W13: =SUMIF('05'!D:D,Summary!$B13,'05'!E:E) -> 40 | X13: =SUMIF('06'!D:D,Summary!$B13,'06'!E:E) -> 96 | Y13: =SUMIF('07'!D:D,Summary!$B13,'07'!E:E) -> 96 | Z13: =SUMIF('08'!D:D,Summary!$B13,'08'!E:E) -> 96 | AA13: =SUMIF('09'!D:D,Summary!$B13,'09'!E:E) -> 104 | AB13: =SUMIF('10'!D:D,Summary!$B13,'10'!E:E) -> 48 | AC13: =SUMIF('11'!D:D,Summary!$B13,'11'!E:E) -> 48 | AD13: =SUMIF('12'!D:D,Summary!$B13,'12'!E:E) -> 0 | AE13: =SUMIF('13'!D:D,Summary!$B13,'13'!E:E) -> 0 | AF13: =SUMIF('14'!D:D,Summary!$B13,'14'!E:E) -> 0 | AG13: =SUMIF('15'!D:D,Summary!$B13,'15'!E:E) -> 0 | AH13: =SUMIF('16'!D:D,Summary!$B13,'16'!E:E) -> 0 | AI13: =SUMIF('17'!D:D,Summary!$B13,'17'!E:E) -> 0 | AJ13: =SUMIF('18'!D:D,Summary!$B13,'18'!E:E) -> 0 | AK13: =SUMIF('19'!D:D,Summary!$B13,'19'!E:E) -> 0 | AL13: =SUMIF('20'!D:D,Summary!$B13,'20'!E:E) -> 0 | AM13: =SUMIF('21'!D:D,Summary!$B13,'21'!E:E) -> 0 | AN13: =SUMIF('22'!D:D,Summary!$B13,'22'!$E:$E) -> 0 | AO13: =SUMIF(#REF!,Summary!$B13,#REF!) -> #REF! | AP13: =SUMIF(#REF!,Summary!$B13,#REF!) -> #REF! | AQ13: =SUMIF(#REF!,Summary!$B13,#REF!) -> #REF! | AR13: =SUMIF(#REF!,Summary!$B13,#REF!) -> #REF! | AS13: =SUMIF(#REF!,Summary!$B13,#REF!) -> #REF! | AT13: =SUMIF('28'!D:D,Summary!$B13,'28'!E:E) -> 0 | AU13: =SUMIF('29'!D:D,Summary!$B13,'29'!E:E) -> 0 | AV13: =SUMIF('30'!D:D,Summary!$B13,'30'!E:E) -> 0 | AW13: =SUMIF('31'!D:D,Summary!$B13,'31'!E:E) -> 0 | AX13: =SUMIF('32'!D:D,Summary!$B13,'32'!E:E) -> 0 | AY13: =SUMIF('33'!D:D,Summary!$B13,'33'!E:E) -> 0 | AZ13: =SUMIF('34'!D:D,Summary!$B13,'34'!E:E) -> 0 | BA13: =SUMIF('35'!D:D,Summary!$B13,'35'!E:E) -> 0 | BB13: =SUMIF('36'!D:D,Summary!$B13,'36'!E:E) -> 0 | BC13: =SUMIF('37'!D:D,Summary!$B13,'37'!E:E) -> 0 | BD13: =SUMIF('38'!D:D,Summary!$B13,'38'!E:E) -> 0 | BE13: =SUMIF('39'!D:D,Summary!$B13,'39'!E:E) -> 0 | BF13: =SUMIF('40'!D:D,Summary!$B13,'40'!E:E) -> 0 | BG13: =SUMIF('41'!D:D,Summary!$B13,'41'!E:E) -> 0 | BH13: =SUMIF('42'!D:D,Summary!$B13,'42'!E:E) -> 0 | BI13: =SUMIF('43'!D:D,Summary!$B13,'43'!E:E) -> 0 | BJ13: =SUMIF('44'!D:D,Summary!$B13,'44'!E:E) -> 0 | BK13: =SUMIF('45'!D:D,Summary!$B13,'45'!E:E) -> 0 | BL13: =SUMIF('46'!D:D,Summary!$B13,'46'!E:E) -> 0 | BM13: =SUMIF('47'!D:D,Summary!$B13,'47'!E:E) -> 0 | BN13: =SUMIF('48'!D:D,Summary!$B13,'48'!E:E) -> 0 | BO13: =SUMIF('49'!D:D,Summary!$B13,'49'!E:E) -> 0 | BP13: =SUMIF('50'!D:D,Summary!$B13,'50'!E:E) -> 0 | BQ13: =SUMIF('51'!D:D,Summary!$B13,'51'!E:E) -> 0 | BR13: =SUMIF('52'!D:D,Summary!$B13,'52'!E:E) -> 0 | BS13: =SUMIF('53'!D:D,Summary!$B13,'53'!E:E) -> 0
A14: =A13+1 -> 11 | B14: FA242 | D14: =S14+T14+U14+V14+W14 -> 0 | E14: =X14+Y14+Z14+AA14 -> 0 | F14: =AB14+AC14+AD14+AE14 -> 0 | G14: =AF14+AG14+AH14+AI14+AJ14 -> 168 | H14: =AK14+AL14+AM14+AN14 -> 0 | I14: =AO14+AP14+AQ14+AR14 -> #REF! | J14: =AS14+AT14+AU14+AV14+AW14 -> #REF! | K14: =AX14+AY14+AZ14+BA14 -> 0 | L14: =BB14+BC14+BD14+BE14 -> 0 | M14: =BF14+BG14+BH14+BI14+BJ14 -> 0 | N14: =BK14+BL14+BM14+BN14 -> 0 | O14: =BO14+BP14+BQ14+BR14+BS14 -> 0 | P14: =(SUM(S14:BS14)) -> #REF! | R14: =IF(Q14>P14,Q14-P14,0) -> #REF! | S14: =SUMIF('01'!D:D,Summary!$B14,'01'!E:E) -> 0 | T14: =SUMIF('02'!D:D,Summary!$B14,'02'!E:E) -> 0 | U14: =SUMIF('03'!D:D,Summary!$B14,'03'!E:E) -> 0 | V14: =SUMIF('04'!D:D,Summary!$B14,'04'!E:E) -> 0 | W14: =SUMIF('05'!D:D,Summary!$B14,'05'!E:E) -> 0 | X14: =SUMIF('06'!D:D,Summary!$B14,'06'!E:E) -> 0 | Y14: =SUMIF('07'!D:D,Summary!$B14,'07'!E:E) -> 0 | Z14: =SUMIF('08'!D:D,Summary!$B14,'08'!E:E) -> 0 | AA14: =SUMIF('09'!D:D,Summary!$B14,'09'!E:E) -> 0 | AB14: =SUMIF('10'!D:D,Summary!$B14,'10'!E:E) -> 0 | AC14: =SUMIF('11'!D:D,Summary!$B14,'11'!E:E) -> 0 | AD14: =SUMIF('12'!D:D,Summary!$B14,'12'!E:E) -> 0 | AE14: =SUMIF('13'!D:D,Summary!$B14,'13'!E:E) -> 0 | AF14: =SUMIF('14'!D:D,Summary!$B14,'14'!E:E) -> 112 | AG14: =SUMIF('15'!D:D,Summary!$B14,'15'!E:E) -> 56 | AH14: =SUMIF('16'!D:D,Summary!$B14,'16'!E:E) -> 0 | AI14: =SUMIF('17'!D:D,Summary!$B14,'17'!E:E) -> 0 | AJ14: =SUMIF('18'!D:D,Summary!$B14,'18'!E:E) -> 0 | AK14: =SUMIF('19'!D:D,Summary!$B14,'19'!E:E) -> 0 | AL14: =SUMIF('20'!D:D,Summary!$B14,'20'!E:E) -> 0 | AM14: =SUMIF('21'!D:D,Summary!$B14,'21'!E:E) -> 0 | AN14: =SUMIF('22'!D:D,Summary!$B14,'22'!$E:$E) -> 0 | AO14: =SUMIF(#REF!,Summary!$B14,#REF!) -> #REF! | AP14: =SUMIF(#REF!,Summary!$B14,#REF!) -> #REF! | AQ14: =SUMIF(#REF!,Summary!$B14,#REF!) -> #REF! | AR14: =SUMIF(#REF!,Summary!$B14,#REF!) -> #REF! | AS14: =SUMIF(#REF!,Summary!$B14,#REF!) -> #REF! | AT14: =SUMIF('28'!D:D,Summary!$B14,'28'!E:E) -> 0 | AU14: =SUMIF('29'!D:D,Summary!$B14,'29'!E:E) -> 0 | AV14: =SUMIF('30'!D:D,Summary!$B14,'30'!E:E) -> 0 | AW14: =SUMIF('31'!D:D,Summary!$B14,'31'!E:E) -> 0 | AX14: =SUMIF('32'!D:D,Summary!$B14,'32'!E:E) -> 0 | AY14: =SUMIF('33'!D:D,Summary!$B14,'33'!E:E) -> 0 | AZ14: =SUMIF('34'!D:D,Summary!$B14,'34'!E:E) -> 0 | BA14: =SUMIF('35'!D:D,Summary!$B14,'35'!E:E) -> 0 | BB14: =SUMIF('36'!D:D,Summary!$B14,'36'!E:E) -> 0 | BC14: =SUMIF('37'!D:D,Summary!$B14,'37'!E:E) -> 0 | BD14: =SUMIF('38'!D:D,Summary!$B14,'38'!E:E) -> 0 | BE14: =SUMIF('39'!D:D,Summary!$B14,'39'!E:E) -> 0 | BF14: =SUMIF('40'!D:D,Summary!$B14,'40'!E:E) -> 0 | BG14: =SUMIF('41'!D:D,Summary!$B14,'41'!E:E) -> 0 | BH14: =SUMIF('42'!D:D,Summary!$B14,'42'!E:E) -> 0 | BI14: =SUMIF('43'!D:D,Summary!$B14,'43'!E:E) -> 0 | BJ14: =SUMIF('44'!D:D,Summary!$B14,'44'!E:E) -> 0 | BK14: =SUMIF('45'!D:D,Summary!$B14,'45'!E:E) -> 0 | BL14: =SUMIF('46'!D:D,Summary!$B14,'46'!E:E) -> 0 | BM14: =SUMIF('47'!D:D,Summary!$B14,'47'!E:E) -> 0 | BN14: =SUMIF('48'!D:D,Summary!$B14,'48'!E:E) -> 0 | BO14: =SUMIF('49'!D:D,Summary!$B14,'49'!E:E) -> 0 | BP14: =SUMIF('50'!D:D,Summary!$B14,'50'!E:E) -> 0 | BQ14: =SUMIF('51'!D:D,Summary!$B14,'51'!E:E) -> 0 | BR14: =SUMIF('52'!D:D,Summary!$B14,'52'!E:E) -> 0 | BS14: =SUMIF('53'!D:D,Summary!$B14,'53'!E:E) -> 0
A15: =A14+1 -> 12 | B15: FA243 | D15: =S15+T15+U15+V15+W15 -> 108 | E15: =X15+Y15+Z15+AA15 -> 32 | F15: =AB15+AC15+AD15+AE15 -> 0 | G15: =AF15+AG15+AH15+AI15+AJ15 -> 0 | H15: =AK15+AL15+AM15+AN15 -> 0 | I15: =AO15+AP15+AQ15+AR15 -> #REF! | J15: =AS15+AT15+AU15+AV15+AW15 -> #REF! | K15: =AX15+AY15+AZ15+BA15 -> 0 | L15: =BB15+BC15+BD15+BE15 -> 0 | M15: =BF15+BG15+BH15+BI15+BJ15 -> 0 | N15: =BK15+BL15+BM15+BN15 -> 0 | O15: =BO15+BP15+BQ15+BR15+BS15 -> 0 | P15: =(SUM(S15:BS15)) -> #REF! | R15: =IF(Q15>P15,Q15-P15,0) -> #REF! | S15: =SUMIF('01'!D:D,Summary!$B15,'01'!E:E) -> 0 | T15: =SUMIF('02'!D:D,Summary!$B15,'02'!E:E) -> 0 | U15: =SUMIF('03'!D:D,Summary!$B15,'03'!E:E) -> 36 | V15: =SUMIF('04'!D:D,Summary!$B15,'04'!E:E) -> 56 | W15: =SUMIF('05'!D:D,Summary!$B15,'05'!E:E) -> 16 | X15: =SUMIF('06'!D:D,Summary!$B15,'06'!E:E) -> 24 | Y15: =SUMIF('07'!D:D,Summary!$B15,'07'!E:E) -> 8 | Z15: =SUMIF('08'!D:D,Summary!$B15,'08'!E:E) -> 0 | AA15: =SUMIF('09'!D:D,Summary!$B15,'09'!E:E) -> 0 | AB15: =SUMIF('10'!D:D,Summary!$B15,'10'!E:E) -> 0 | AC15: =SUMIF('11'!D:D,Summary!$B15,'11'!E:E) -> 0 | AD15: =SUMIF('12'!D:D,Summary!$B15,'12'!E:E) -> 0 | AE15: =SUMIF('13'!D:D,Summary!$B15,'13'!E:E) -> 0 | AF15: =SUMIF('14'!D:D,Summary!$B15,'14'!E:E) -> 0 | AG15: =SUMIF('15'!D:D,Summary!$B15,'15'!E:E) -> 0 | AH15: =SUMIF('16'!D:D,Summary!$B15,'16'!E:E) -> 0 | AI15: =SUMIF('17'!D:D,Summary!$B15,'17'!E:E) -> 0 | AJ15: =SUMIF('18'!D:D,Summary!$B15,'18'!E:E) -> 0 | AK15: =SUMIF('19'!D:D,Summary!$B15,'19'!E:E) -> 0 | AL15: =SUMIF('20'!D:D,Summary!$B15,'20'!E:E) -> 0 | AM15: =SUMIF('21'!D:D,Summary!$B15,'21'!E:E) -> 0 | AN15: =SUMIF('22'!D:D,Summary!$B15,'22'!$E:$E) -> 0 | AO15: =SUMIF(#REF!,Summary!$B15,#REF!) -> #REF! | AP15: =SUMIF(#REF!,Summary!$B15,#REF!) -> #REF! | AQ15: =SUMIF(#REF!,Summary!$B15,#REF!) -> #REF! | AR15: =SUMIF(#REF!,Summary!$B15,#REF!) -> #REF! | AS15: =SUMIF(#REF!,Summary!$B15,#REF!) -> #REF! | AT15: =SUMIF('28'!D:D,Summary!$B15,'28'!E:E) -> 0 | AU15: =SUMIF('29'!D:D,Summary!$B15,'29'!E:E) -> 0 | AV15: =SUMIF('30'!D:D,Summary!$B15,'30'!E:E) -> 0 | AW15: =SUMIF('31'!D:D,Summary!$B15,'31'!E:E) -> 0 | AX15: =SUMIF('32'!D:D,Summary!$B15,'32'!E:E) -> 0 | AY15: =SUMIF('33'!D:D,Summary!$B15,'33'!E:E) -> 0 | AZ15: =SUMIF('34'!D:D,Summary!$B15,'34'!E:E) -> 0 | BA15: =SUMIF('35'!D:D,Summary!$B15,'35'!E:E) -> 0 | BB15: =SUMIF('36'!D:D,Summary!$B15,'36'!E:E) -> 0 | BC15: =SUMIF('37'!D:D,Summary!$B15,'37'!E:E) -> 0 | BD15: =SUMIF('38'!D:D,Summary!$B15,'38'!E:E) -> 0 | BE15: =SUMIF('39'!D:D,Summary!$B15,'39'!E:E) -> 0 | BF15: =SUMIF('40'!D:D,Summary!$B15,'40'!E:E) -> 0 | BG15: =SUMIF('41'!D:D,Summary!$B15,'41'!E:E) -> 0 | BH15: =SUMIF('42'!D:D,Summary!$B15,'42'!E:E) -> 0 | BI15: =SUMIF('43'!D:D,Summary!$B15,'43'!E:E) -> 0 | BJ15: =SUMIF('44'!D:D,Summary!$B15,'44'!E:E) -> 0 | BK15: =SUMIF('45'!D:D,Summary!$B15,'45'!E:E) -> 0 | BL15: =SUMIF('46'!D:D,Summary!$B15,'46'!E:E) -> 0 | BM15: =SUMIF('47'!D:D,Summary!$B15,'47'!E:E) -> 0 | BN15: =SUMIF('48'!D:D,Summary!$B15,'48'!E:E) -> 0 | BO15: =SUMIF('49'!D:D,Summary!$B15,'49'!E:E) -> 0 | BP15: =SUMIF('50'!D:D,Summary!$B15,'50'!E:E) -> 0 | BQ15: =SUMIF('51'!D:D,Summary!$B15,'51'!E:E) -> 0 | BR15: =SUMIF('52'!D:D,Summary!$B15,'52'!E:E) -> 0 | BS15: =SUMIF('53'!D:D,Summary!$B15,'53'!E:E) -> 0
A16: =A15+1 -> 13 | B16: FA244 | D16: =S16+T16+U16+V16+W16 -> 128 | E16: =X16+Y16+Z16+AA16 -> 38 | F16: =AB16+AC16+AD16+AE16 -> 0 | G16: =AF16+AG16+AH16+AI16+AJ16 -> 0 | H16: =AK16+AL16+AM16+AN16 -> 256 | I16: =AO16+AP16+AQ16+AR16 -> #REF! | J16: =AS16+AT16+AU16+AV16+AW16 -> #REF! | K16: =AX16+AY16+AZ16+BA16 -> 0 | L16: =BB16+BC16+BD16+BE16 -> 0 | M16: =BF16+BG16+BH16+BI16+BJ16 -> 0 | N16: =BK16+BL16+BM16+BN16 -> 0 | O16: =BO16+BP16+BQ16+BR16+BS16 -> 0 | P16: =(SUM(S16:BS16)) -> #REF! | R16: =IF(Q16>P16,Q16-P16,0) -> #REF! | S16: =SUMIF('01'!D:D,Summary!$B16,'01'!E:E) -> 48 | T16: =SUMIF('02'!D:D,Summary!$B16,'02'!E:E) -> 64 | U16: =SUMIF('03'!D:D,Summary!$B16,'03'!E:E) -> 16 | V16: =SUMIF('04'!D:D,Summary!$B16,'04'!E:E) -> 0 | W16: =SUMIF('05'!D:D,Summary!$B16,'05'!E:E) -> 0 | X16: =SUMIF('06'!D:D,Summary!$B16,'06'!E:E) -> 0 | Y16: =SUMIF('07'!D:D,Summary!$B16,'07'!E:E) -> 32 | Z16: =SUMIF('08'!D:D,Summary!$B16,'08'!E:E) -> 6 | AA16: =SUMIF('09'!D:D,Summary!$B16,'09'!E:E) -> 0 | AB16: =SUMIF('10'!D:D,Summary!$B16,'10'!E:E) -> 0 | AC16: =SUMIF('11'!D:D,Summary!$B16,'11'!E:E) -> 0 | AD16: =SUMIF('12'!D:D,Summary!$B16,'12'!E:E) -> 0 | AE16: =SUMIF('13'!D:D,Summary!$B16,'13'!E:E) -> 0 | AF16: =SUMIF('14'!D:D,Summary!$B16,'14'!E:E) -> 0 | AG16: =SUMIF('15'!D:D,Summary!$B16,'15'!E:E) -> 0 | AH16: =SUMIF('16'!D:D,Summary!$B16,'16'!E:E) -> 0 | AI16: =SUMIF('17'!D:D,Summary!$B16,'17'!E:E) -> 0 | AJ16: =SUMIF('18'!D:D,Summary!$B16,'18'!E:E) -> 0 | AK16: =SUMIF('19'!D:D,Summary!$B16,'19'!E:E) -> 120 | AL16: =SUMIF('20'!D:D,Summary!$B16,'20'!E:E) -> 40 | AM16: =SUMIF('21'!D:D,Summary!$B16,'21'!E:E) -> 48 | AN16: =SUMIF('22'!D:D,Summary!$B16,'22'!$E:$E) -> 48 | AO16: =SUMIF(#REF!,Summary!$B16,#REF!) -> #REF! | AP16: =SUMIF(#REF!,Summary!$B16,#REF!) -> #REF! | AQ16: =SUMIF(#REF!,Summary!$B16,#REF!) -> #REF! | AR16: =SUMIF(#REF!,Summary!$B16,#REF!) -> #REF! | AS16: =SUMIF(#REF!,Summary!$B16,#REF!) -> #REF! | AT16: =SUMIF('28'!D:D,Summary!$B16,'28'!E:E) -> 0 | AU16: =SUMIF('29'!D:D,Summary!$B16,'29'!E:E) -> 0 | AV16: =SUMIF('30'!D:D,Summary!$B16,'30'!E:E) -> 0 | AW16: =SUMIF('31'!D:D,Summary!$B16,'31'!E:E) -> 0 | AX16: =SUMIF('32'!D:D,Summary!$B16,'32'!E:E) -> 0 | AY16: =SUMIF('33'!D:D,Summary!$B16,'33'!E:E) -> 0 | AZ16: =SUMIF('34'!D:D,Summary!$B16,'34'!E:E) -> 0 | BA16: =SUMIF('35'!D:D,Summary!$B16,'35'!E:E) -> 0 | BB16: =SUMIF('36'!D:D,Summary!$B16,'36'!E:E) -> 0 | BC16: =SUMIF('37'!D:D,Summary!$B16,'37'!E:E) -> 0 | BD16: =SUMIF('38'!D:D,Summary!$B16,'38'!E:E) -> 0 | BE16: =SUMIF('39'!D:D,Summary!$B16,'39'!E:E) -> 0 | BF16: =SUMIF('40'!D:D,Summary!$B16,'40'!E:E) -> 0 | BG16: =SUMIF('41'!D:D,Summary!$B16,'41'!E:E) -> 0 | BH16: =SUMIF('42'!D:D,Summary!$B16,'42'!E:E) -> 0 | BI16: =SUMIF('43'!D:D,Summary!$B16,'43'!E:E) -> 0 | BJ16: =SUMIF('44'!D:D,Summary!$B16,'44'!E:E) -> 0 | BK16: =SUMIF('45'!D:D,Summary!$B16,'45'!E:E) -> 0 | BL16: =SUMIF('46'!D:D,Summary!$B16,'46'!E:E) -> 0 | BM16: =SUMIF('47'!D:D,Summary!$B16,'47'!E:E) -> 0 | BN16: =SUMIF('48'!D:D,Summary!$B16,'48'!E:E) -> 0 | BO16: =SUMIF('49'!D:D,Summary!$B16,'49'!E:E) -> 0 | BP16: =SUMIF('50'!D:D,Summary!$B16,'50'!E:E) -> 0 | BQ16: =SUMIF('51'!D:D,Summary!$B16,'51'!E:E) -> 0 | BR16: =SUMIF('52'!D:D,Summary!$B16,'52'!E:E) -> 0 | BS16: =SUMIF('53'!D:D,Summary!$B16,'53'!E:E) -> 0
... A72: =A71+1 -> 69 | B72: FA300 | D72: =S72+T72+U72+V72+W72 -> 0 | E72: =X72+Y72+Z72+AA72 -> 0 | F72: =AB72+AC72+AD72+AE72 -> 0 | G72: =AF72+AG72+AH72+AI72+AJ72 -> 0 | H72: =AK72+AL72+AM72+AN72 -> 0 | I72: =AO72+AP72+AQ72+AR72 -> #REF! | J72: =AS72+AT72+AU72+AV72+AW72 -> #REF! | K72: =AX72+AY72+AZ72+BA72 -> 0 | L72: =BB72+BC72+BD72+BE72 -> 0 | M72: =BF72+BG72+BH72+BI72+BJ72 -> 0 | N72: =BK72+BL72+BM72+BN72 -> 0 | O72: =BO72+BP72+BQ72+BR72+BS72 -> 0 | P72: =(SUM(S72:BS72)) -> #REF! | R72: =IF(Q72>P72,Q72-P72,0) -> #REF! | S72: =SUMIF('01'!D:D,Summary!$B72,'01'!E:E) -> 0 | T72: =SUMIF('02'!D:D,Summary!$B72,'02'!E:E) -> 0 | U72: =SUMIF('03'!D:D,Summary!$B72,'03'!E:E) -> 0 | V72: =SUMIF('04'!D:D,Summary!$B72,'04'!E:E) -> 0 | W72: =SUMIF('05'!D:D,Summary!$B72,'05'!E:E) -> 0 | X72: =SUMIF('06'!D:D,Summary!$B72,'06'!E:E) -> 0 | Y72: =SUMIF('07'!D:D,Summary!$B72,'07'!E:E) -> 0 | Z72: =SUMIF('08'!D:D,Summary!$B72,'08'!E:E) -> 0 | AA72: =SUMIF('09'!D:D,Summary!$B72,'09'!E:E) -> 0 | AB72: =SUMIF('10'!D:D,Summary!$B72,'10'!E:E) -> 0 | AC72: =SUMIF('11'!D:D,Summary!$B72,'11'!E:E) -> 0 | AD72: =SUMIF('12'!D:D,Summary!$B72,'12'!E:E) -> 0 | AE72: =SUMIF('13'!D:D,Summary!$B72,'13'!E:E) -> 0 | AF72: =SUMIF('14'!D:D,Summary!$B72,'14'!E:E) -> 0 | AG72: =SUMIF('15'!D:D,Summary!$B72,'15'!E:E) -> 0 | AH72: =SUMIF('16'!D:D,Summary!$B72,'16'!E:E) -> 0 | AI72: =SUMIF('17'!D:D,Summary!$B72,'17'!E:E) -> 0 | AJ72: =SUMIF('18'!D:D,Summary!$B72,'18'!E:E) -> 0 | AK72: =SUMIF('19'!D:D,Summary!$B72,'19'!E:E) -> 0 | AL72: =SUMIF('20'!D:D,Summary!$B72,'20'!E:E) -> 0 | AM72: =SUMIF('21'!D:D,Summary!$B72,'21'!E:E) -> 0 | AN72: =SUMIF('22'!D:D,Summary!$B72,'22'!$E:$E) -> 0 | AO72: =SUMIF(#REF!,Summary!$B72,#REF!) -> #REF! | AP72: =SUMIF(#REF!,Summary!$B72,#REF!) -> #REF! | AQ72: =SUMIF(#REF!,Summary!$B72,#REF!) -> #REF! | AR72: =SUMIF(#REF!,Summary!$B72,#REF!) -> #REF! | AS72: =SUMIF(#REF!,Summary!$B72,#REF!) -> #REF! | AT72: =SUMIF('28'!D:D,Summary!$B72,'28'!E:E) -> 0 | AU72: =SUMIF('29'!D:D,Summary!$B72,'29'!E:E) -> 0 | AV72: =SUMIF('30'!D:D,Summary!$B72,'30'!E:E) -> 0 | AW72: =SUMIF('31'!D:D,Summary!$B72,'31'!E:E) -> 0 | AX72: =SUMIF('32'!D:D,Summary!$B72,'32'!E:E) -> 0 | AY72: =SUMIF('33'!D:D,Summary!$B72,'33'!E:E) -> 0 | AZ72: =SUMIF('34'!D:D,Summary!$B72,'34'!E:E) -> 0 | BA72: =SUMIF('35'!D:D,Summary!$B72,'35'!E:E) -> 0 | BB72: =SUMIF('36'!D:D,Summary!$B72,'36'!E:E) -> 0 | BC72: =SUMIF('37'!D:D,Summary!$B72,'37'!E:E) -> 0 | BD72: =SUMIF('38'!D:D,Summary!$B72,'38'!E:E) -> 0 | BE72: =SUMIF('39'!D:D,Summary!$B72,'39'!E:E) -> 0 | BF72: =SUMIF('40'!D:D,Summary!$B72,'40'!E:E) -> 0 | BG72: =SUMIF('41'!D:D,Summary!$B72,'41'!E:E) -> 0 | BH72: =SUMIF('42'!D:D,Summary!$B72,'42'!E:E) -> 0 | BI72: =SUMIF('43'!D:D,Summary!$B72,'43'!E:E) -> 0 | BJ72: =SUMIF('44'!D:D,Summary!$B72,'44'!E:E) -> 0 | BK72: =SUMIF('45'!D:D,Summary!$B72,'45'!E:E) -> 0 | BL72: =SUMIF('46'!D:D,Summary!$B72,'46'!E:E) -> 0 | BM72: =SUMIF('47'!D:D,Summary!$B72,'47'!E:E) -> 0 | BN72: =SUMIF('48'!D:D,Summary!$B72,'48'!E:E) -> 0 | BO72: =SUMIF('49'!D:D,Summary!$B72,'49'!E:E) -> 0 | BP72: =SUMIF('50'!D:D,Summary!$B72,'50'!E:E) -> 0 | BQ72: =SUMIF('51'!D:D,Summary!$B72,'51'!E:E) -> 0 | BR72: =SUMIF('52'!D:D,Summary!$B72,'52'!E:E) -> 0 | BS72: =SUMIF('53'!D:D,Summary!$B72,'53'!E:E) -> 0
A73: =A72+1 -> 70 | D73: =S73+T73+U73+V73+W73 -> 0 | E73: =X73+Y73+Z73+AA73 -> 0 | F73: =AB73+AC73+AD73+AE73 -> 0 | G73: =AF73+AG73+AH73+AI73+AJ73 -> 0 | H73: =AK73+AL73+AM73+AN73 -> 0 | I73: =AO73+AP73+AQ73+AR73 -> #REF! | J73: =AS73+AT73+AU73+AV73+AW73 -> #REF! | K73: =AX73+AY73+AZ73+BA73 -> 0 | L73: =BB73+BC73+BD73+BE73 -> 0 | M73: =BF73+BG73+BH73+BI73+BJ73 -> 0 | N73: =BK73+BL73+BM73+BN73 -> 0 | O73: =BO73+BP73+BQ73+BR73+BS73 -> 0 | P73: =(SUM(S73:BS73)) -> #REF! | R73: =IF(Q73>P73,Q73-P73,0) -> #REF! | S73: =SUMIF('01'!D:D,Summary!$B73,'01'!E:E) -> 0 | T73: =SUMIF('02'!D:D,Summary!$B73,'02'!E:E) -> 0 | U73: =SUMIF('03'!D:D,Summary!$B73,'03'!E:E) -> 0 | V73: =SUMIF('04'!D:D,Summary!$B73,'04'!E:E) -> 0 | W73: =SUMIF('05'!D:D,Summary!$B73,'05'!E:E) -> 0 | X73: =SUMIF('06'!D:D,Summary!$B73,'06'!E:E) -> 0 | Y73: =SUMIF('07'!D:D,Summary!$B73,'07'!E:E) -> 0 | Z73: =SUMIF('08'!D:D,Summary!$B73,'08'!E:E) -> 0 | AA73: =SUMIF('09'!D:D,Summary!$B73,'09'!E:E) -> 0 | AB73: =SUMIF('10'!D:D,Summary!$B73,'10'!E:E) -> 0 | AC73: =SUMIF('11'!D:D,Summary!$B73,'11'!E:E) -> 0 | AD73: =SUMIF('12'!D:D,Summary!$B73,'12'!E:E) -> 0 | AE73: =SUMIF('13'!D:D,Summary!$B73,'13'!E:E) -> 0 | AF73: =SUMIF('14'!D:D,Summary!$B73,'14'!E:E) -> 0 | AG73: =SUMIF('15'!D:D,Summary!$B73,'15'!E:E) -> 0 | AH73: =SUMIF('16'!D:D,Summary!$B73,'16'!E:E) -> 0 | AI73: =SUMIF('17'!D:D,Summary!$B73,'17'!E:E) -> 0 | AJ73: =SUMIF('18'!D:D,Summary!$B73,'18'!E:E) -> 0 | AK73: =SUMIF('19'!D:D,Summary!$B73,'19'!E:E) -> 0 | AL73: =SUMIF('20'!D:D,Summary!$B73,'20'!E:E) -> 0 | AM73: =SUMIF('21'!D:D,Summary!$B73,'21'!E:E) -> 0 | AN73: =SUMIF('22'!D:D,Summary!$B73,'22'!$E:$E) -> 0 | AO73: =SUMIF(#REF!,Summary!$B73,#REF!) -> #REF! | AP73: =SUMIF(#REF!,Summary!$B73,#REF!) -> #REF! | AQ73: =SUMIF(#REF!,Summary!$B73,#REF!) -> #REF! | AR73: =SUMIF(#REF!,Summary!$B73,#REF!) -> #REF! | AS73: =SUMIF(#REF!,Summary!$B73,#REF!) -> #REF! | AT73: =SUMIF('28'!D:D,Summary!$B73,'28'!E:E) -> 0 | AU73: =SUMIF('29'!D:D,Summary!$B73,'29'!E:E) -> 0 | AV73: =SUMIF('30'!D:D,Summary!$B73,'30'!E:E) -> 0 | AW73: =SUMIF('31'!D:D,Summary!$B73,'31'!E:E) -> 0 | AX73: =SUMIF('32'!D:D,Summary!$B73,'32'!E:E) -> 0 | AY73: =SUMIF('33'!D:D,Summary!$B73,'33'!E:E) -> 0 | AZ73: =SUMIF('34'!D:D,Summary!$B73,'34'!E:E) -> 0 | BA73: =SUMIF('35'!D:D,Summary!$B73,'35'!E:E) -> 0 | BB73: =SUMIF('36'!D:D,Summary!$B73,'36'!E:E) -> 0 | BC73: =SUMIF('37'!D:D,Summary!$B73,'37'!E:E) -> 0 | BD73: =SUMIF('38'!D:D,Summary!$B73,'38'!E:E) -> 0 | BE73: =SUMIF('39'!D:D,Summary!$B73,'39'!E:E) -> 0 | BF73: =SUMIF('40'!D:D,Summary!$B73,'40'!E:E) -> 0 | BG73: =SUMIF('41'!D:D,Summary!$B73,'41'!E:E) -> 0 | BH73: =SUMIF('42'!D:D,Summary!$B73,'42'!E:E) -> 0 | BI73: =SUMIF('43'!D:D,Summary!$B73,'43'!E:E) -> 0 | BJ73: =SUMIF('44'!D:D,Summary!$B73,'44'!E:E) -> 0 | BK73: =SUMIF('45'!D:D,Summary!$B73,'45'!E:E) -> 0 | BL73: =SUMIF('46'!D:D,Summary!$B73,'46'!E:E) -> 0 | BM73: =SUMIF('47'!D:D,Summary!$B73,'47'!E:E) -> 0 | BN73: =SUMIF('48'!D:D,Summary!$B73,'48'!E:E) -> 0 | BO73: =SUMIF('49'!D:D,Summary!$B73,'49'!E:E) -> 0 | BP73: =SUMIF('50'!D:D,Summary!$B73,'50'!E:E) -> 0 | BQ73: =SUMIF('51'!D:D,Summary!$B73,'51'!E:E) -> 0 | BR73: =SUMIF('52'!D:D,Summary!$B73,'52'!E:E) -> 0 | BS73: =SUMIF('53'!D:D,Summary!$B73,'53'!E:E) -> 0

Sheet 01
B1: Daily plan | F1: Date :- | G1: 46020
B3: S.No. | C3: Employee name | D3: PROJECT CODES | E3: Actual time to finish
B4: 1 | C4: SUSHIL URKUDE | D4: FA257 | E4: 8
B5: 2 | C5: SAKET SHAIKH | D5: FA266 | E5: 8
B6: 3 | C6: AMOL MANDLIK | D6: FA257 | E6: 8
B7: 4 | C7: BABASO GORE | D7: FA257 | E7: 8
B8: 5 | C8: KUNDAN KOLI | D8: FA257 | E8: 8
B9: 6 | C9: PRASAD RAKSHE | D9: FA257 | E9: 8
B10: 7 | C10: SHUBHAM MANE | D10: FA265 | E10: 8
B11: 8 | C11: SURAJ DIGHE | D11: FA257 | E11: 8
B12: 9 | C12: SANKET GHANWAT | D12: FA241 | E12: 8
B13: 10 | C13: ROHAN KHARAT | D13: FA257 | E13: 8
B14: 11 | C14: KEVIN VEGAD | D14: FA257 | E14: 8
B15: 12 | C15: ABHISHEKH TELANG | D15: FA257 | E15: 8
... B27: 24 | C27: Abdul Nadaf | D27: FA259 | E27: 8
B28: 25 | C28: SURAJ GAIKWAD
B29: 26 | C29: AJAY NAVTHAR
B30: 27 | C30: RAVINDRA MATE
B31: 28 | C31: KETAN MATE
B32: 29 | C32: ANURAG MANE
B33: 30 | C33: JOTIBA PATIL
B34: 31 | C34: VAIBHAV GUND
B35: 32 | C35: ABHISHEK BOKMURKAR
B36: 33 | C36: SURAJ MAHADIK
B37: 34 | C37: RUPESH SURYWANSHI
B38: 35 | C38: VIKAS SURUSHE | D38: FA249 | E38: 8
B39: 36 | C39: ABHISHEK MHASKE | D39: FA263 | E39: 0
B40: 37 | C40: SHUBHAM POREDI | D40: FA249 | E40: 8
B41: 38 | C41: VISHAL PATIL | D41: FA263 | E41: 0
B42: 39 | C42: UMANG PATEL | D42: FA249 | E42: 8
B43: 40 | C43: AKSHAY GAVADE | D43: FA263 | E43: 0
B44: 41 | C44: AYUSH PATIL | D44: FA263 | E44: 0
B45: 42 | C45: HARSHAL PAWAR | D45: FA263 | E45: 0
B46: 43 | C46: MAYUR SALUNKHE | D46: FA263 | E46: 0
B47: 44 | C47: KISHOR GOPALE | D47: FA263 | E47: 8
B48: 45 | C48: MANI SHANKAR | D48: FA263 | E48: 8
B49: 46 | C49: VISHAL GAWADE | D49: FA259 | E49: 8
... B72: 69 | C72: DNYANESHWAR KARATE | D72: FA257 | E72: 8
B73: 70
B74: 71 | C74: PARAG CHAUDHARI | D74: FA260 | E74: 8
...

Sheet 02
B1: Daily plan | F1: Date :- | G1: ='01'!G1+7 -> 46027
B3: S.No. | C3: Employee name | D3: PROJECT CODES | E3: Actual time to finish
B4: 1 | C4: SUSHIL URKUDE | D4: FA257 | E4: 8
B5: 2 | C5: SAKET SHAIKH | D5: FA266 | E5: 8
B6: 3 | C6: AMOL MANDLIK | D6: FA257 | E6: 8
B7: 4 | C7: BABASO GORE | D7: FA257 | E7: 8
B8: 5 | C8: KUNDAN KOLI | D8: FA257 | E8: 8
B9: 6 | C9: PRASAD RAKSHE | D9: FA257 | E9: 8
B10: 7 | C10: SHUBHAM MANE | D10: FA265 | E10: 8
B11: 8 | C11: SURAJ DIGHE | D11: FA257 | E11: 8
B12: 9 | C12: SANKET GHANWAT | D12: FA241 | E12: 8
B13: 10 | C13: ROHAN KHARAT | D13: FA257 | E13: 8
B14: 11 | C14: KEVIN VEGAD | D14: FA257 | E14: 8
B15: 12 | C15: ABHISHEKH TELANG | D15: FA257 | E15: 8
... B27: 24 | C27: Abdul Nadaf | D27: FA259 | E27: 8
B28: 25 | C28: SURAJ GAIKWAD
B29: 26 | C29: AJAY NAVTHAR
B30: 27 | C30: RAVINDRA MATE
B31: 28 | C31: KETAN MATE
B32: 29 | C32: ANURAG MANE
B33: 30 | C33: JOTIBA PATIL
B34: 31 | C34: VAIBHAV GUND
B35: 32 | C35: ABHISHEK BOKMURKAR
B36: 33 | C36: SURAJ MAHADIK
B37: 34 | C37: RUPESH SURYWANSHI
B38: 35 | C38: VIKAS SURUSHE | D38: FA249 | E38: 8
B39: 36 | C39: ABHISHEK MHASKE | D39: FA263 | E39: 0
B40: 37 | C40: SHUBHAM POREDI | D40: FA249 | E40: 8
B41: 38 | C41: VISHAL PATIL | D41: FA263 | E41: 0
B42: 39 | C42: UMANG PATEL | D42: FA249 | E42: 8
B43: 40 | C43: AKSHAY GAVADE | D43: FA263 | E43: 0
B44: 41 | C44: AYUSH PATIL | D44: FA263 | E44: 0
B45: 42 | C45: HARSHAL PAWAR | D45: FA263 | E45: 0
B46: 43 | C46: MAYUR SALUNKHE | D46: FA263 | E46: 0
B47: 44 | C47: KISHOR GOPALE | D47: FA263 | E47: 8
B48: 45 | C48: MANI SHANKAR | D48: FA263 | E48: 8
B49: 46 | C49: VISHAL GAWADE | D49: FA259 | E49: 8
... B72: 69 | C72: DNYANESHWAR KARATE | D72: FA257 | E72: 8
B73: 70
B74: 71 | C74: PARAG CHAUDHARI | D74: FA260 | E74: 8
...

Sheet 03
B1: Daily plan | F1: Date :- | G1: ='02'!G1+7 -> 46034
B3: S.No. | C3: Employee name | D3: PROJECT CODES | E3: Actual time to finish
B4: 1 | C4: SUSHIL URKUDE | D4: FA257 | E4: 8
B5: 2 | C5: SAKET SHAIKH | D5: FA266 | E5: 8
B6: 3 | C6: AMOL MANDLIK | D6: FA257 | E6: 8
B7: 4 | C7: BABASO GORE | D7: FA257 | E7: 8
B8: 5 | C8: KUNDAN KOLI | D8: FA257 | E8: 8
B9: 6 | C9: PRASAD RAKSHE | D9: FA257 | E9: 8
B10: 7 | C10: SHUBHAM MANE | D10: FA265 | E10: 8
B11: 8 | C11: SURAJ DIGHE | D11: FA257 | E11: 8
B12: 9 | C12: SANKET GHANWAT | D12: FA241 | E12: 8
B13: 10 | C13: ROHAN KHARAT | D13: FA257 | E13: 8
B14: 11 | C14: KEVIN VEGAD | D14: FA257 | E14: 8
B15: 12 | C15: ABHISHEKH TELANG | D15: FA257 | E15: 8
... B27: 24 | C27: Abdul Nadaf | D27: FA259 | E27: 8
B28: 25 | C28: SURAJ GAIKWAD
B29: 26 | C29: AJAY NAVTHAR
B30: 27 | C30: RAVINDRA MATE
B31: 28 | C31: KETAN MATE
B32: 29 | C32: ANURAG MANE
B33: 30 | C33: JOTIBA PATIL
B34: 31 | C34: VAIBHAV GUND
B35: 32 | C35: ABHISHEK BOKMURKAR
B36: 33 | C36: SURAJ MAHADIK
B37: 34 | C37: RUPESH SURYWANSHI
B38: 35 | C38: VIKAS SURUSHE | D38: FA249 | E38: 8
B39: 36 | C39: ABHISHEK MHASKE | D39: FA263 | E39: 0
B40: 37 | C40: SHUBHAM POREDI | D40: FA249 | E40: 8
B41: 38 | C41: VISHAL PATIL | D41: FA263 | E41: 0
B42: 39 | C42: UMANG PATEL | D42: FA249 | E42: 8
B43: 40 | C43: AKSHAY GAVADE | D43: FA263 | E43: 0
B44: 41 | C44: AYUSH PATIL | D44: FA263 | E44: 0
B45: 42 | C45: HARSHAL PAWAR | D45: FA263 | E45: 0
B46: 43 | C46: MAYUR SALUNKHE | D46: FA263 | E46: 0
B47: 44 | C47: KISHOR GOPALE | D47: FA263 | E47: 8
B48: 45 | C48: MANI SHANKAR | D48: FA263 | E48: 8
B49: 46 | C49: VISHAL GAWADE | D49: FA259 | E49: 8
... B72: 69 | C72: DNYANESHWAR KARATE | D72: FA257 | E72: 8
B73: 70
B74: 71 | C74: PARAG CHAUDHARI | D74: FA260 | E74: 8
...

Sheet 04
B1: Daily plan | F1: Date :- | G1: ='03'!G1+7 -> 46041
B3: S.No. | C3: Employee name | D3: PROJECT CODES | E3: Actual time to finish
B4: 1 | C4: SUSHIL URKUDE | D4: FA257 | E4: 8
B5: 2 | C5: SAKET SHAIKH | D5: FA266 | E5: 8
B6: 3 | C6: AMOL MANDLIK | D6: FA257 | E6: 8
B7: 4 | C7: BABASO GORE | D7: FA257 | E7: 8
B8: 5 | C8: KUNDAN KOLI | D8: FA257 | E8: 8
B9: 6 | C9: PRASAD RAKSHE | D9: FA257 | E9: 8
B10: 7 | C10: SHUBHAM MANE | D10: FA265 | E10: 8
B11: 8 | C11: SURAJ DIGHE | D11: FA257 | E11: 8
B12: 9 | C12: SANKET GHANWAT | D12: FA241 | E12: 8
B13: 10 | C13: ROHAN KHARAT | D13: FA257 | E13: 8
B14: 11 | C14: KEVIN VEGAD | D14: FA257 | E14: 8
B15: 12 | C15: ABHISHEKH TELANG | D15: FA257 | E15: 8
... B27: 24 | C27: Abdul Nadaf | D27: FA259 | E27: 8
B28: 25 | C28: SURAJ GAIKWAD
B29: 26 | C29: AJAY NAVTHAR
B30: 27 | C30: RAVINDRA MATE
B31: 28 | C31: KETAN MATE
B32: 29 | C32: ANURAG MANE
B33: 30 | C33: JOTIBA PATIL
B34: 31 | C34: VAIBHAV GUND
B35: 32 | C35: ABHISHEK BOKMURKAR
B36: 33 | C36: SURAJ MAHADIK
B37: 34 | C37: RUPESH SURYWANSHI
B38: 35 | C38: VIKAS SURUSHE | D38: FA249 | E38: 8
B39: 36 | C39: ABHISHEK MHASKE | D39: FA263 | E39: 0
B40: 37 | C40: SHUBHAM POREDI | D40: FA249 | E40: 8
B41: 38 | C41: VISHAL PATIL | D41: FA263 | E41: 0
B42: 39 | C42: UMANG PATEL | D42: FA249 | E42: 8
B43: 40 | C43: AKSHAY GAVADE | D43: FA263 | E43: 0
B44: 41 | C44: AYUSH PATIL | D44: FA263 | E44: 0
B45: 42 | C45: HARSHAL PAWAR | D45: FA263 | E45: 0
B46: 43 | C46: MAYUR SALUNKHE | D46: FA263 | E46: 0
B47: 44 | C47: KISHOR GOPALE | D47: FA263 | E47: 8
B48: 45 | C48: MANI SHANKAR | D48: FA263 | E48: 8
B49: 46 | C49: VISHAL GAWADE | D49: FA259 | E49: 8
... B72: 69 | C72: DNYANESHWAR KARATE | D72: FA257 | E72: 8
B73: 70
B74: 71 | C74: PARAG CHAUDHARI | D74: FA260 | E74: 8
...

Sheet 05
B1: Daily plan | F1: Date :- | G1: ='04'!G1+7 -> 46048
B3: S.No. | C3: Employee name | D3: PROJECT CODES | E3: Actual time to finish
B4: 1 | C4: SUSHIL URKUDE | D4: FA257
B5: 2 | C5: SAKET SHAIKH | D5: FA266
B6: 3 | C6: AMOL MANDLIK | D6: FA257
B7: 4 | C7: BABASO GORE | D7: FA257
B8: 5 | C8: KUNDAN KOLI | D8: FA257
B9: 6 | C9: PRASAD RAKSHE | D9: FA257
B10: 7 | C10: SHUBHAM MANE | D10: FA265
B11: 8 | C11: SURAJ DIGHE | D11: FA257
B12: 9 | C12: SANKET GHANWAT | D12: FA241
B13: 10 | C13: ROHAN KHARAT | D13: FA257
B14: 11 | C14: KEVIN VEGAD | D14: FA257
B15: 12 | C15: ABHISHEKH TELANG | D15: FA257
... B27: 24 | C27: Abdul Nadaf | D27: FA259
B28: 25 | C28: SURAJ GAIKWAD
B29: 26 | C29: AJAY NAVTHAR
B30: 27 | C30: RAVINDRA MATE
B31: 28 | C31: KETAN MATE
B32: 29 | C32: ANURAG MANE
B33: 30 | C33: JOTIBA PATIL
B34: 31 | C34: VAIBHAV GUND
B35: 32 | C35: ABHISHEK BOKMURKAR
B36: 33 | C36: SURAJ MAHADIK
B37: 34 | C37: RUPESH SURYWANSHI
B38: 35 | C38: VIKAS SURUSHE | D38: FA249
B39: 36 | C39: ABHISHEK MHASKE | D39: FA263
B40: 37 | C40: SHUBHAM POREDI | D40: FA249
B41: 38 | C41: VISHAL PATIL | D41: FA263
B42: 39 | C42: UMANG PATEL | D42: FA249
B43: 40 | C43: AKSHAY GAVADE | D43: FA263
B44: 41 | C44: AYUSH PATIL | D44: FA263
B45: 42 | C45: HARSHAL PAWAR | D45: FA263
B46: 43 | C46: MAYUR SALUNKHE | D46: FA263
B47: 44 | C47: KISHOR GOPALE | D47: FA263
B48: 45 | C48: MANI SHANKAR | D48: FA263
B49: 46 | C49: VISHAL GAWADE | D49: FA259
... B72: 69 | C72: DNYANESHWAR KARATE | D72: FA257
B73: 70
B74: 71 | C74: PARAG CHAUDHARI | D74: FA260
...

Sheet 06
B1: Daily plan | F1: Date :- | G1: ='05'!G1+7 -> 46055
B3: S.No. | C3: Employee name | D3: PROJECT CODES | E3: Actual time to finish
B4: 1 | C4: SUSHIL URKUDE | D4: FA257 | E4: 8
B5: 2 | C5: SAKET SHAIKH | D5: FA266 | E5: 8
B6: 3 | C6: AMOL MANDLIK | D6: FA257 | E6: 8
B7: 4 | C7: BABASO GORE | D7: FA257 | E7: 8
B8: 5 | C8: KUNDAN KOLI | D8: FA257 | E8: 8
B9: 6 | C9: PRASAD RAKSHE | D9: FA257 | E9: 8
B10: 7 | C10: SHUBHAM MANE | D10: FA265 | E10: 8
B11: 8 | C11: SURAJ DIGHE | D11: FA257 | E11: 8
B12: 9 | C12: SANKET GHANWAT | D12: FA241 | E12: 8
B13: 10 | C13: ROHAN KHARAT | D13: FA257 | E13: 8
B14: 11 | C14: KEVIN VEGAD | D14: FA257 | E14: 8
B15: 12 | C15: ABHISHEKH TELANG | D15: FA257 | E15: 8
... B27: 24 | C27: Abdul Nadaf | D27: FA259 | E27: 8
B28: 25 | C28: SURAJ GAIKWAD
B29: 26 | C29: AJAY NAVTHAR
B30: 27 | C30: RAVINDRA MATE
B31: 28 | C31: KETAN MATE
B32: 29 | C32: ANURAG MANE
B33: 30 | C33: JOTIBA PATIL
B34: 31 | C34: VAIBHAV GUND
B35: 32 | C35: ABHISHEK BOKMURKAR
B36: 33 | C36: SURAJ MAHADIK
B37: 34 | C37: RUPESH SURYWANSHI
B38: 35 | C38: VIKAS SURUSHE
B39: 36 | C39: ABHISHEK MHASKE
... B42: 39 | C42: UMANG PATEL
B43: 40
B44: 41 | C44: AYUSH PATIL
B45: 42 | C45: HARSHAL PAWAR
B46: 43 | C46: MAYUR SALUNKHE
B47: 44 | C47: KISHOR GOPALE | D47: FA263 | E47: 8
B48: 45 | C48: MANI SHANKAR | D48: FA263 | E48: 8
B49: 46 | C49: VISHAL GAWADE | D49: FA259 | E49: 8
B50: 47 | C50: SACHIN ROHAKALE | D50: FA259 | E50: 8
B51: 48 | C51: SHREYA CHAVHAN | D51: FA259 | E51: 8
B52: 49 | C52: SHEKHAR PAWAR | D52: FA259 | E52: 8
B53: 50 | C53: PRATHAMESH ROKADE | D53: FA258 | E53: 8
B54: 51 | C54: RAKESH BISEN | D54: FA259 | E54: 8
...

Sheet 07
B1: Daily plan | F1: Date :- | G1: ='06'!G1+7 -> 46062
B3: S.No. | C3: Employee name | D3: PROJECT CODES | E3: Actual time to finish
B4: 1 | C4: SUSHIL URKUDE | D4: FA257 | E4: 8
B5: 2 | C5: SAKET SHAIKH | D5: FA266 | E5: 8
B6: 3 | C6: AMOL MANDLIK | D6: FA257 | E6: 8
B7: 4 | C7: BABASO GORE | D7: FA257 | E7: 8
B8: 5 | C8: KUNDAN KOLI | D8: FA257 | E8: 8
B9: 6 | C9: PRASAD RAKSHE | D9: FA257 | E9: 8
B10: 7 | C10: SHUBHAM MANE | D10: FA265 | E10: 8
B11: 8 | C11: SURAJ DIGHE | D11: FA257 | E11: 8
B12: 9 | C12: SANKET GHANWAT | D12: FA241 | E12: 8
B13: 10 | C13: ROHAN KHARAT | D13: FA257 | E13: 8
B14: 11 | C14: KEVIN VEGAD | D14: FA257 | E14: 8
B15: 12 | C15: ABHISHEKH TELANG | D15: FA257 | E15: 8
